Workbook

Sheet crimesUSA
A1: ETAT | B1: ETAT_abr | C1: ANNEE | D1: T_INFRACTION | E1: T_CAMBRIOLAGE | F1: T_VOL | G1: T_VOL_AUTO | H1: T_CRIME_VIOLENT | I1: T_MENACE | J1: T_MEURTRE | K1: T_VIOL | L1: T_AGRESSION_PHYSIQUE | M1: TOTAL_INFRACTION | N1: TOTAL_CAMBRIOLAGE | O1: TOTAL_VOL | P1: TOTAL_VOL_AUTO | Q1: TOTAL_CRIME_VIOLENT | R1: TOTAL_MENACE | S1: TOTAL_MEURTRE | T1: TOTAL_VIOL | U1: TOTAL_AGRESSION_PHYSIQUE | V1: POPULATION | W1: SURFACE_KM2 | X1: TAUX_PAUVRETE | Y1: TAUX_COLLEGE_GRAD | Z1: TAUX_PARTICIPATION_2016 | AA1: TAUX_URBANISATION | AB1: PIB_2019 | AC1: PEINE_DE_MORT | AD1: POSITION_GEO | AE1: PERIPHERIE | AF1: CLIMAT
A2: ALASKA | B2: AK | C2: 2019 | D2: 2910.8 | E2: 487.1 | F2: 2066 | G2: 357.7 | H2: 867.1 | I2: 596 | J2: 9.4 | K2: 148.7 | L2: 112.9 | M2: 21294 | N2: 3563 | O2: 15114 | P2: 2617 | Q2: 6343 | R2: 4360 | S2: 69 | T2: 1088 | U2: 826 | V2: 731545 | W2: 1481305 | X2: 11.4 | Y2: 26 | Z2: 60 - 65% | AA2: 65 | AB2: 51 | AC2: Non | AD2: Ouest | AE2: Autre | AF2: Continental froid
A3: ALABAMA | B3: AL | C3: 2019 | D3: 2674.4 | E3: 531.9 | F3: 1886.1 | G3: 256.5 | H3: 510.8 | I3: 381 | J3: 7.3 | K3: 42.2 | L3: 80.4 | M3: 131133 | N3: 26079 | O3: 92477 | P3: 12577 | Q3: 25046 | R3: 18679 | S3: 358 | T3: 2068 | U3: 3941 | V3: 4903185 | W3: 131171 | X3: 19.2 | Y3: 52 | Z3: 55 - 60 % | AA3: 58 | AB3: 214 | AC3: Oui | AD3: Sud | AE3: Peripherie | AF3: Subtropical humide
A4: ARKANSAS | B4: AR | C4: 2019 | D4: 2858 | E4: 599.6 | F4: 2012.6 | G4: 245.9 | H4: 584.6 | I4: 447.8 | J4: 8 | K4: 77.2 | L4: 51.6 | M4: 86250 | N4: 18095 | O4: 60735 | P4: 7420 | Q4: 17643 | R4: 13513 | S4: 242 | T4: 2331 | U4: 1557 | V4: 3017804 | W4: 134771 | X4: 18.7 | Y4: 47 | Z4: 50 - 55 % | AA4: 56 | AB4: 123 | AC4: Oui | AD4: Sud | AE4: Centre | AF4: Subtropical humide
A5: ARIZONA | B5: AZ | C5: 2019 | D5: 2440.5 | E5: 394.3 | F5: 1796.9 | G5: 249.4 | H5: 455.3 | I5: 311.9 | J5: 5 | K5: 50.3 | L5: 88.1 | M5: 177638 | N5: 28699 | O5: 130788 | P5: 18151 | Q5: 33141 | R5: 22704 | S5: 365 | T5: 3662 | U5: 6410 | V5: 7278717 | W5: 294207 | X5: 18.2 | Y5: 26 | Z5: Moins de 50 % | AA5: 89 | AB5: 339 | AC5: Oui | AD5: Ouest | AE5: Peripherie | AF5: Desertique et semi-aride chaud
A6: CALIFORNIA | B6: CA | C6: 2019 | D6: 2331.2 | E6: 386.1 | F6: 1586.3 | G6: 358.8 | H6: 441.2 | I6: 267.1 | J6: 4.3 | K6: 37.5 | L6: 132.4 | M6: 921114 | N6: 152555 | O6: 626802 | P6: 141757 | Q6: 174331 | R6: 105541 | S6: 1690 | T6: 14799 | U6: 52301 | V6: 39512223 | W6: 403466 | X6: 16.4 | Y6: 64 | Z6: Moins de 50 % | AA6: 94 | AB6: 2905 | AC6: Moratoire | AD6: Ouest | AE6: Peripherie | AF6: Mediteraneen
A7: COLORADO | B7: CO | C7: 2019 | D7: 2590.7 | E7: 348.4 | F7: 1858.3 | G7: 384 | H7: 381 | I7: 246.3 | J7: 3.8 | K7: 67.2 | L7: 63.6 | M7: 149189 | N7: 20064 | O7: 107012 | P7: 22113 | Q7: 21938 | R7: 14185 | S7: 218 | T7: 3872 | U7: 3663 | V7: 5758736 | W7: 268431 | X7: 12.1 | Y7: 54 | Z7: Plus de 65 % | AA7: 86 | AB7: 361 | AC7: Oui | AD7: Ouest | AE7: Centre | AF7: Semi-aride - steppes
A8: CONNECTICUT | B8: CT | C8: 2019 | D8: 1426.6 | E8: 180.7 | F8: 1078.7 | G8: 167.3 | H8: 183.6 | I8: 105 | J8: 2.9 | K8: 21.6 | L8: 54.1 | M8: 50862 | N8: 6441 | O8: 38457 | P8: 5964 | Q8: 6546 | R8: 3742 | S8: 104 | T8: 771 | U8: 1929 | V8: 3565287 | W8: 12542 | X8: 10.8 | Y8: 68 | Z8: 55 - 60 % | AA8: 86 | AB8: 265 | AC8: Non | AD8: Nord-Est | AE8: Peripherie | AF8: Continental humide
A9: DELAWARE | B9: DE | C9: 2019 | D9: 2252.2 | E9: 304.8 | F9: 1782.7 | G9: 164.7 | H9: 422.6 | I9: 304.7 | J9: 4.9 | K9: 31.8 | L9: 81.1 | M9: 21931 | N9: 2968 | O9: 17359 | P9: 1604 | Q9: 4115 | R9: 2967 | S9: 48 | T9: 310 | U9: 790 | V9: 973764 | W9: 5047 | X9: 13 | Y9: 65 | Z9: 60 - 65% | AA9: 83 | AB9: 70 | AC9: Non | AD9: Sud | AE9: Peripherie | AF9: Continental humide
A10: FLORIDA | B10: FL | C10: 2019 | D10: 2145.7 | E10: 295.2 | F10: 1668.7 | G10: 181.8 | H10: 378.4 | I10: 258.3 | J10: 5.2 | K10: 39.4 | L10: 75.5 | M10: 460846 | N10: 63396 | O10: 358402 | P10: 39048 | Q10: 81270 | R10: 55475 | S10: 1122 | T10: 8456 | U10: 16217 | V10: 21477737 | W10: 138887 | X10: 16.6 | Y10: 56 | Z10: 60 - 65% | AA10: 92 | AB10: 1013 | AC10: Oui | AD10: Sud | AE10: Peripherie | AF10: Subtropical humide
A11: GEORGIA | B11: GA | C11: 2019 | D11: 2375.8 | E11: 372.1 | F11: 1779.8 | G11: 223.9 | H11: 340.7 | I11: 232 | J11: 6.2 | K11: 27.5 | L11: 75 | M11: 252249 | N11: 39506 | O11: 188967 | P11: 23776 | Q11: 36170 | R11: 24633 | S11: 654 | T11: 2922 | U11: 7961 | V11: 10617423 | W11: 10617423 | X11: 18.4 | Y11: 43 | Z11: 55 - 60 % | AA11: 74 | AB11: 571 | AC11: Oui | AD11: Sud | AE11: Peripherie | AF11: Subtropical humide
A12: HAWAI | B12: HI | C12: 2019 | D12: 2841.2 | E12: 377.2 | F12: 2093 | G12: 371.1 | H12: 285.5 | I12: 148.2 | J12: 3.4 | K12: 54 | L12: 79.9 | M12: 40228 | N12: 5340 | O12: 29634 | P12: 5254 | Q12: 4042 | R12: 2098 | S12: 48 | T12: 765 | U12: 1131 | V12: 1415872 | W12: 16635 | X12: 11.5 | Y12: 53 | Z12: Moins de 50 % | AA12: 86 | AB12: 90 | AC12: Non | AD12: Ouest | AE12: Autre | AF12: Tropical
A13: IOWA | B13: IA | C13: 2019 | D13: 1733.7 | E13: 371.1 | F13: 1199.6 | G13: 163 | H13: 266.6 | I13: 200.4 | J13: 1.9 | K13: 36.9 | L13: 27.4 | M13: 54699 | N13: 11710 | O13: 37847 | P13: 5142 | Q13: 8410 | R13: 6323 | S13: 60 | T13: 1164 | U13: 863 | V13: 3155070 | W13: 144669 | X13: 12.3 | Y13: 68 | Z13: Plus de 65 % | AA13: 63 | AB13: 181 | AC13: Non | AD13: Centre-Ouest | AE13: Centre | AF13: Continental humide
... A51: WYOMING | B51: WY | C51: 2019 | D51: 1571.1 | E51: 241.2 | F51: 1206.7 | G51: 123.2 | H51: 217.4 | I51: 147.6 | J51: 2.2 | K51: 56 | L51: 11.6 | M51: 9093 | N51: 1396 | O51: 6984 | P51: 713 | Q51: 1258 | R51: 854 | S51: 13 | T51: 324 | U51: 67 | V51: 578759 | W51: 251470 | X51: 10.6 | Y51: 58 | Z51: 55 - 60 % | AA51: 62 | AB51: 37 | AC51: Oui | AD51: Ouest | AE51: Centre | AF51: Semi-aride - steppes

Sheet Données brutes
A1: NOM : | B1: ABRIC--SEGARRA | E1: NOM du Binôme (s'il y en a un) :
A2: Prénom : | B2: Maxence
A3: Groupe : | B3: C
B9: CAMBRIOLAGE | C9: VOL | D9: VOL_AUTO | E9: MENACE | F9: MEURTRE | G9: VIOL | H9: AGRESSION_PHYSIQUE | K9: CAMBRIOLAGE | L9: VOL | M9: VOL_AUTO | N9: MENACE | O9: MEURTRE | P9: VIOL | Q9: AGRESSION_PHYSIQUE
A10: Les 3 - | B10: =INDEX(crimesUSA[ETAT],MATCH(SMALL(crimesUSA[T_CAMBRIOLAGE],1),crimesUSA[T_CAMBRIOLAGE],0)) -> NEW HAMPSHIRE | C10: =INDEX(crimesUSA[ETAT],MATCH(SMALL(crimesUSA[T_VOL],1),crimesUSA[T_VOL],0)) -> IDAHO | D10: =INDEX(crimesUSA[ETAT],MATCH(SMALL(crimesUSA[T_VOL_AUTO],1),crimesUSA[T_VOL_AUTO],0)) -> VERMONT | E10: =INDEX(crimesUSA[ETAT],MATCH(SMALL(crimesUSA[T_MENACE],1),crimesUSA[T_MENACE],0)) -> MAINE | F10: =INDEX(crimesUSA[ETAT],MATCH(SMALL(crimesUSA[T_MEURTRE],1),crimesUSA[T_MEURTRE],0)) -> MAINE | G10: =INDEX(crimesUSA[ETAT],MATCH(SMALL(crimesUSA[T_VIOL],1),crimesUSA[T_VIOL],0)) -> NEW JERSEY | H10: =INDEX(crimesUSA[ETAT],MATCH(SMALL(crimesUSA[T_AGRESSION_PHYSIQUE],1),crimesUSA[T_AGRESSION_PHYSIQUE],0)) -> IDAHO
B11: =INDEX(crimesUSA[ETAT],MATCH(SMALL(crimesUSA[T_CAMBRIOLAGE],2),crimesUSA[T_CAMBRIOLAGE],0)) -> NEW YORK | C11: =INDEX(crimesUSA[ETAT],MATCH(SMALL(crimesUSA[T_VOL],3),crimesUSA[T_VOL],0)) -> MAINE | D11: =INDEX(crimesUSA[ETAT],MATCH(SMALL(crimesUSA[T_VOL_AUTO],2),crimesUSA[T_VOL_AUTO],0)) -> MAINE | E11: =INDEX(crimesUSA[ETAT],MATCH(SMALL(crimesUSA[T_MENACE],2),crimesUSA[T_MENACE],0)) -> NEW HAMPSHIRE | F11: =INDEX(crimesUSA[ETAT],MATCH(SMALL(crimesUSA[T_MEURTRE],2),crimesUSA[T_MEURTRE],0)) -> VERMONT | G11: =INDEX(crimesUSA[ETAT],MATCH(SMALL(crimesUSA[T_VIOL],2),crimesUSA[T_VIOL],0)) -> CONNECTICUT | H11: =INDEX(crimesUSA[ETAT],MATCH(SMALL(crimesUSA[T_AGRESSION_PHYSIQUE],2),crimesUSA[T_AGRESSION_PHYSIQUE],0)) -> VERMONT | J11: Min | K11: =MIN(crimesUSA[T_CAMBRIOLAGE]) -> 126.3 | L11: =MIN(crimesUSA[T_VOL]) -> 911.8 | M11: =MIN(crimesUSA[T_VOL_AUTO]) -> 47.8 | N11: =MIN(crimesUSA[T_MENACE]) -> 61.3 | O11: =MIN(crimesUSA[T_MEURTRE]) -> 1.5 | P11: =MIN(crimesUSA[T_VIOL]) -> 17.2 | Q11: =MIN(crimesUSA[T_AGRESSION_PHYSIQUE]) -> 8.7
B12: =INDEX(crimesUSA[ETAT],MATCH(SMALL(crimesUSA[T_CAMBRIOLAGE],3),crimesUSA[T_CAMBRIOLAGE],0)) -> VIRGINIA | C12: =INDEX(crimesUSA[ETAT],MATCH(SMALL(crimesUSA[T_VOL],4),crimesUSA[T_VOL],0)) -> NEW HAMPSHIRE | D12: =INDEX(crimesUSA[ETAT],MATCH(SMALL(crimesUSA[T_VOL_AUTO],3),crimesUSA[T_VOL_AUTO],0)) -> NEW YORK | E12: =INDEX(crimesUSA[ETAT],MATCH(SMALL(crimesUSA[T_MENACE],3),crimesUSA[T_MENACE],0)) -> CONNECTICUT | F12: =INDEX(crimesUSA[ETAT],MATCH(SMALL(crimesUSA[T_MEURTRE],3),crimesUSA[T_MEURTRE],0)) -> IOWA | G12: =INDEX(crimesUSA[ETAT],MATCH(SMALL(crimesUSA[T_VIOL],3),crimesUSA[T_VIOL],0)) -> MISSISSIPPI | H12: =INDEX(crimesUSA[ETAT],MATCH(SMALL(crimesUSA[T_AGRESSION_PHYSIQUE],3),crimesUSA[T_AGRESSION_PHYSIQUE],0)) -> WYOMING | J12: Max | K12: =MAX(crimesUSA[T_CAMBRIOLAGE]) -> 696.8 | L12: =MAX(crimesUSA[T_VOL]) -> 2352.4 | M12: =MAX(crimesUSA[T_VOL_AUTO]) -> 427.2 | N12: =MAX(crimesUSA[T_MENACE]) -> 650.5 | O12: =MAX(crimesUSA[T_MEURTRE]) -> 11.7 | P12: =MAX(crimesUSA[T_VIOL]) -> 148.7 | Q12: =MAX(crimesUSA[T_AGRESSION_PHYSIQUE]) -> 152.2
J13: Moyenne | K13: =AVERAGE(crimesUSA[T_CAMBRIOLAGE]) -> 347.296 | L13: =AVERAGE(crimesUSA[T_VOL]) -> 1536.456 | M13: =AVERAGE(crimesUSA[T_VOL_AUTO]) -> 212.93 | N13: =AVERAGE(crimesUSA[T_MENACE]) -> 250.504 | O13: =AVERAGE(crimesUSA[T_MEURTRE]) -> 4.778 | P13: =AVERAGE(crimesUSA[T_VIOL]) -> 47.632 | Q13: =AVERAGE(crimesUSA[T_AGRESSION_PHYSIQUE]) -> 62.584
J14: Q2 | K14: =_xlfn.QUARTILE.INC(crimesUSA[T_CAMBRIOLAGE],2) -> 335.45 | L14: =_xlfn.QUARTILE.INC(crimesUSA[T_VOL],2) -> 1546 | M14: =_xlfn.QUARTILE.INC(crimesUSA[T_VOL_AUTO],2) -> 201.35 | N14: =_xlfn.QUARTILE.INC(crimesUSA[T_MENACE],2) -> 243.65 | O14: =_xlfn.QUARTILE.INC(crimesUSA[T_MEURTRE],2) -> 4.5 | P14: =_xlfn.QUARTILE.INC(crimesUSA[T_VIOL],2) -> 44.2 | Q14: =_xlfn.QUARTILE.INC(crimesUSA[T_AGRESSION_PHYSIQUE],2) -> 61.75
A15: Les 3 + | B15: =INDEX(crimesUSA[ETAT],MATCH(LARGE(crimesUSA[T_CAMBRIOLAGE],1),crimesUSA[T_CAMBRIOLAGE],0)) -> NEW MEXICO | C15: =INDEX(crimesUSA[ETAT],MATCH(LARGE(crimesUSA[T_VOL],1),crimesUSA[T_VOL],0)) -> LOUISIANA | D15: =INDEX(crimesUSA[ETAT],MATCH(LARGE(crimesUSA[T_VOL_AUTO],1),crimesUSA[T_VOL_AUTO],0)) -> NEW MEXICO | E15: =INDEX(crimesUSA[ETAT],MATCH(LARGE(crimesUSA[T_MENACE],1),crimesUSA[T_MENACE],0)) -> NEW MEXICO | F15: =INDEX(crimesUSA[ETAT],MATCH(LARGE(crimesUSA[T_MEURTRE],1),crimesUSA[T_MEURTRE],0)) -> LOUISIANA | G15: =INDEX(crimesUSA[ETAT],MATCH(LARGE(crimesUSA[T_VIOL],1),crimesUSA[T_VIOL],0)) -> ALASKA | H15: =INDEX(crimesUSA[ETAT],MATCH(LARGE(crimesUSA[T_AGRESSION_PHYSIQUE],1),crimesUSA[T_AGRESSION_PHYSIQUE],0)) -> MARYLAND | J15: Ecart type | K15: =_xlfn.STDEV.P(crimesUSA[T_CAMBRIOLAGE]) -> 140.95538 | L15: =_xlfn.STDEV.P(crimesUSA[T_VOL]) -> 363.34145 | M15: =_xlfn.STDEV.P(crimesUSA[T_VOL_AUTO]) -> 95.985422 | N15: =_xlfn.STDEV.P(crimesUSA[T_MENACE]) -> 118.93335 | O15: =_xlfn.STDEV.P(crimesUSA[T_MEURTRE]) -> 2.6086234 | P15: =_xlfn.STDEV.P(crimesUSA[T_VIOL]) -> 19.636155 | Q15: =_xlfn.STDEV.P(crimesUSA[T_AGRESSION_PHYSIQUE]) -> 32.004514
B16: =INDEX(crimesUSA[ETAT],MATCH(LARGE(crimesUSA[T_CAMBRIOLAGE],2),crimesUSA[T_CAMBRIOLAGE],0)) -> OKLAHOMA | C16: =INDEX(crimesUSA[ETAT],MATCH(LARGE(crimesUSA[T_VOL],2),crimesUSA[T_VOL],0)) -> SOUTH CAROLINA | D16: =INDEX(crimesUSA[ETAT],MATCH(LARGE(crimesUSA[T_VOL_AUTO],2),crimesUSA[T_VOL_AUTO],0)) -> COLORADO | E16: =INDEX(crimesUSA[ETAT],MATCH(LARGE(crimesUSA[T_MENACE],2),crimesUSA[T_MENACE],0)) -> ALASKA | F16: =INDEX(crimesUSA[ETAT],MATCH(LARGE(crimesUSA[T_MEURTRE],2),crimesUSA[T_MEURTRE],0)) -> MISSISSIPPI | G16: =INDEX(crimesUSA[ETAT],MATCH(LARGE(crimesUSA[T_VIOL],2),crimesUSA[T_VIOL],0)) -> ARKANSAS | H16: =INDEX(crimesUSA[ETAT],MATCH(LARGE(crimesUSA[T_AGRESSION_PHYSIQUE],2),crimesUSA[T_AGRESSION_PHYSIQUE],0)) -> CALIFORNIA
B17: =INDEX(crimesUSA[ETAT],MATCH(LARGE(crimesUSA[T_CAMBRIOLAGE],3),crimesUSA[T_CAMBRIOLAGE],0)) -> MISSISSIPPI | C17: =INDEX(crimesUSA[ETAT],MATCH(LARGE(crimesUSA[T_VOL],3),crimesUSA[T_VOL],0)) -> HAWAI | D17: =INDEX(crimesUSA[ETAT],MATCH(LARGE(crimesUSA[T_VOL_AUTO],3),crimesUSA[T_VOL_AUTO],0)) -> HAWAI | E17: =INDEX(crimesUSA[ETAT],MATCH(LARGE(crimesUSA[T_MENACE],3),crimesUSA[T_MENACE],0)) -> TENNESSEE | F17: =INDEX(crimesUSA[ETAT],MATCH(LARGE(crimesUSA[T_MEURTRE],3),crimesUSA[T_MEURTRE],0)) -> ALASKA | G17: =INDEX(crimesUSA[ETAT],MATCH(LARGE(crimesUSA[T_VIOL],3),crimesUSA[T_VIOL],0)) -> SOUTH DAKOTA | H17: =INDEX(crimesUSA[ETAT],MATCH(LARGE(crimesUSA[T_AGRESSION_PHYSIQUE],3),crimesUSA[T_AGRESSION_PHYSIQUE],0)) -> ALASKA
B20: Moyennes
A21: POSITION GEOGRAPHIQUE | B21: CAMBRIOLAGE | C21: VOL | D21: VOL_AUTO | E21: MENACE | F21: MEURTRE | G21: VIOL | H21: AGRESSION_PHYSIQUE
A22: Centre-Ouest | B22: =AVERAGEIF(crimesUSA[POSITION_GEO],A22,crimesUSA[T_CAMBRIOLAGE]) -> 315.65 | C22: =AVERAGEIF(crimesUSA[POSITION_GEO],A22,crimesUSA[T_VOL]) -> 1436 | D22: =AVERAGEIF(crimesUSA[POSITION_GEO],A22,crimesUSA[T_VOL_AUTO]) -> 205.225 | E22: =AVERAGEIF(crimesUSA[POSITION_GEO],A22,crimesUSA[T_MENACE]) -> 239.68333 | F22: =AVERAGEIF(crimesUSA[POSITION_GEO],A22,crimesUSA[T_MEURTRE]) -> 4.1333333 | G22: =AVERAGEIF(crimesUSA[POSITION_GEO],A22,crimesUSA[T_VIOL]) -> 51.341667 | H22: =AVERAGEIF(crimesUSA[POSITION_GEO],A22,crimesUSA[T_AGRESSION_PHYSIQUE]) -> 54.425
A23: Nord-Est | B23: =AVERAGEIF(crimesUSA[POSITION_GEO],A23,crimesUSA[T_CAMBRIOLAGE]) -> 177.01111 | C23: =AVERAGEIF(crimesUSA[POSITION_GEO],A23,crimesUSA[T_VOL]) -> 1078.8111 | D23: =AVERAGEIF(crimesUSA[POSITION_GEO],A23,crimesUSA[T_VOL_AUTO]) -> 92.277778 | E23: =AVERAGEIF(crimesUSA[POSITION_GEO],A23,crimesUSA[T_MENACE]) -> 145.64444 | F23: =AVERAGEIF(crimesUSA[POSITION_GEO],A23,crimesUSA[T_MEURTRE]) -> 2.6888889 | G23: =AVERAGEIF(crimesUSA[POSITION_GEO],A23,crimesUSA[T_VIOL]) -> 34.588889 | H23: =AVERAGEIF(crimesUSA[POSITION_GEO],A23,crimesUSA[T_AGRESSION_PHYSIQUE]) -> 47.544444
A24: Ouest | B24: =AVERAGEIF(crimesUSA[POSITION_GEO],A24,crimesUSA[T_CAMBRIOLAGE]) -> 384.90769 | C24: =AVERAGEIF(crimesUSA[POSITION_GEO],A24,crimesUSA[T_VOL]) -> 1713.3231 | D24: =AVERAGEIF(crimesUSA[POSITION_GEO],A24,crimesUSA[T_VOL_AUTO]) -> 295.23077 | E24: =AVERAGEIF(crimesUSA[POSITION_GEO],A24,crimesUSA[T_MENACE]) -> 283.03846 | F24: =AVERAGEIF(crimesUSA[POSITION_GEO],A24,crimesUSA[T_MEURTRE]) -> 4.1076923 | G24: =AVERAGEIF(crimesUSA[POSITION_GEO],A24,crimesUSA[T_VIOL]) -> 60.907692 | H24: =AVERAGEIF(crimesUSA[POSITION_GEO],A24,crimesUSA[T_AGRESSION_PHYSIQUE]) -> 68.569231
A25: Sud | B25: =AVERAGEIF(crimesUSA[POSITION_GEO],A25,crimesUSA[T_CAMBRIOLAGE]) -> 436.25625 | C25: =AVERAGEIF(crimesUSA[POSITION_GEO],A25,crimesUSA[T_VOL]) -> 1725.5187 | D25: =AVERAGEIF(crimesUSA[POSITION_GEO],A25,crimesUSA[T_VOL_AUTO]) -> 219.70625 | E25: =AVERAGEIF(crimesUSA[POSITION_GEO],A25,crimesUSA[T_MENACE]) -> 291.16875 | F25: =AVERAGEIF(crimesUSA[POSITION_GEO],A25,crimesUSA[T_MEURTRE]) -> 6.98125 | G25: =AVERAGEIF(crimesUSA[POSITION_GEO],A25,crimesUSA[T_VIOL]) -> 41.4 | H25: =AVERAGEIF(crimesUSA[POSITION_GEO],A25,crimesUSA[T_AGRESSION_PHYSIQUE]) -> 72.3
A26: Moyenne générale : | B26: =AVERAGE(B22:B25) -> 328.45626 | C26: =AVERAGE(C22:C25) -> 1488.4132 | D26: =AVERAGE(D22:D25) -> 203.10995 | E26: =AVERAGE(E22:E25) -> 239.88375 | F26: =AVERAGE(F22:F25) -> 4.4777911 | G26: =AVERAGE(G22:G25) -> 47.059562 | H26: =AVERAGE(H22:H25) -> 60.709669
A32: d(Colorado; Connecticut) = | C32: =SQRT(SUMXMY2('crimesUSA'!E7:G7, 'crimesUSA'!E8:G8) + SUMXMY2('crimesUSA'!I7:L7, 'crimesUSA'!I8:L8)) -> 839.63948 | E32: avec les 7 variables | F32: Pas de changement majeurs car les variables ne sont pas centrées réduites,
F33: la variable VOL étant très élevés pousse alors vers le haut la distance
A34: d(Colorado; Connecticut) = | C34: =SQRT(SUMXMY2('crimesUSA'!E7:G7,'crimesUSA'!E8:G8)) -> 826.35243 | E34: avec seulement CAMBRIOLAGE, VOL et VOL AUTO
A38: Matrice des corrélations :
B41: CAMBRIOLAGE | C41: VOL | D41: VOL_AUTO | E41: MENACE | F41: MEURTRE | G41: VIOL | H41: AGRESSION_PHYSIQUE
A42: CAMBRIOLAGE | B42: =CORREL(crimesUSA[T_CAMBRIOLAGE],crimesUSA[T_CAMBRIOLAGE]) -> 1 | C42: =CORREL(crimesUSA[T_VOL],crimesUSA[T_CAMBRIOLAGE]) -> 0.73842458 | D42: =CORREL(crimesUSA[T_VOL_AUTO],crimesUSA[T_CAMBRIOLAGE]) -> 0.70241112 | E42: =CORREL(crimesUSA[T_MENACE],crimesUSA[T_CAMBRIOLAGE]) -> 0.67866369 | F42: =CORREL(crimesUSA[T_MEURTRE],crimesUSA[T_CAMBRIOLAGE]) -> 0.70519679 | G42: =CORREL(crimesUSA[T_VIOL],crimesUSA[T_CAMBRIOLAGE]) -> 0.30218418 | H42: =CORREL(crimesUSA[T_AGRESSION_PHYSIQUE],crimesUSA[T_CAMBRIOLAGE]) -> 0.38768639
A43: VOL | B43: =CORREL(crimesUSA[T_CAMBRIOLAGE],crimesUSA[T_VOL]) -> 0.73842458 | C43: =CORREL(crimesUSA[T_VOL],crimesUSA[T_VOL]) -> 1 | D43: =CORREL(crimesUSA[T_VOL_AUTO],crimesUSA[T_VOL]) -> 0.77842451 | E43: =CORREL(crimesUSA[T_MENACE],crimesUSA[T_VOL]) -> 0.61449069 | F43: =CORREL(crimesUSA[T_MEURTRE],crimesUSA[T_VOL]) -> 0.58813154 | G43: =CORREL(crimesUSA[T_VIOL],crimesUSA[T_VOL]) -> 0.3419539 | H43: =CORREL(crimesUSA[T_AGRESSION_PHYSIQUE],crimesUSA[T_VOL]) -> 0.46213562
A44: VOL_AUTO | B44: =CORREL(crimesUSA[T_CAMBRIOLAGE],crimesUSA[T_VOL_AUTO]) -> 0.70241112 | C44: =CORREL(crimesUSA[T_VOL],crimesUSA[T_VOL_AUTO]) -> 0.77842451 | D44: =CORREL(crimesUSA[T_VOL_AUTO],crimesUSA[T_VOL_AUTO]) -> 1 | E44: =CORREL(crimesUSA[T_MENACE],crimesUSA[T_VOL_AUTO]) -> 0.5712858 | F44: =CORREL(crimesUSA[T_MEURTRE],crimesUSA[T_VOL_AUTO]) -> 0.38844495 | G44: =CORREL(crimesUSA[T_VIOL],crimesUSA[T_VOL_AUTO]) -> 0.4415397 | H44: =CORREL(crimesUSA[T_AGRESSION_PHYSIQUE],crimesUSA[T_VOL]) -> 0.46213562
A45: MENACE | B45: =CORREL(crimesUSA[T_CAMBRIOLAGE],crimesUSA[T_MENACE]) -> 0.67866369 | C45: =CORREL(crimesUSA[T_VOL],crimesUSA[T_MENACE]) -> 0.61449069 | D45: =CORREL(crimesUSA[T_VOL_AUTO],crimesUSA[T_MENACE]) -> 0.5712858 | E45: =CORREL(crimesUSA[T_MENACE],crimesUSA[T_MENACE]) -> 1 | F45: =CORREL(crimesUSA[T_MEURTRE],crimesUSA[T_MENACE]) -> 0.6595299 | G45: =CORREL(crimesUSA[T_VIOL],crimesUSA[T_MENACE]) -> 0.546491 | H45: =CORREL(crimesUSA[T_AGRESSION_PHYSIQUE],crimesUSA[T_MENACE]) -> 0.49414002
A46: MEURTRE | B46: =CORREL(crimesUSA[T_CAMBRIOLAGE],crimesUSA[T_MEURTRE]) -> 0.70519679 | C46: =CORREL(crimesUSA[T_VOL],crimesUSA[T_MEURTRE]) -> 0.58813154 | D46: =CORREL(crimesUSA[T_VOL_AUTO],crimesUSA[T_MEURTRE]) -> 0.38844495 | E46: =CORREL(crimesUSA[T_MENACE],crimesUSA[T_MEURTRE]) -> 0.6595299 | F46: =CORREL(crimesUSA[T_MEURTRE],crimesUSA[T_MEURTRE]) -> 1 | G46: =CORREL(crimesUSA[T_VIOL],crimesUSA[T_MEURTRE]) -> 0.16790989 | H46: =CORREL(crimesUSA[T_AGRESSION_PHYSIQUE],crimesUSA[T_MEURTRE]) -> 0.58768936
A47: VIOL | B47: =CORREL(crimesUSA[T_CAMBRIOLAGE],crimesUSA[T_VIOL]) -> 0.30218418 | C47: =CORREL(crimesUSA[T_VOL],crimesUSA[T_VIOL]) -> 0.3419539 | D47: =CORREL(crimesUSA[T_VOL_AUTO],crimesUSA[TOTAL_VIOL]) -> 0.15672864 | E47: =CORREL(crimesUSA[T_MENACE],crimesUSA[T_VIOL]) -> 0.546491 | F47: =CORREL(crimesUSA[T_MEURTRE],crimesUSA[T_VIOL]) -> 0.16790989 | G47: =CORREL(crimesUSA[T_VIOL],crimesUSA[T_VIOL]) -> 1 | H47: =CORREL(crimesUSA[T_AGRESSION_PHYSIQUE],crimesUSA[T_VIOL]) -> 0.071607331
A48: AGRESSION_PHYSIQUE | B48: =CORREL(crimesUSA[T_CAMBRIOLAGE],crimesUSA[T_AGRESSION_PHYSIQUE]) -> 0.38768639 | C48: =CORREL(crimesUSA[T_VOL],crimesUSA[T_AGRESSION_PHYSIQUE]) -> 0.46213562 | D48: =CORREL(crimesUSA[T_VOL_AUTO],crimesUSA[T_AGRESSION_PHYSIQUE]) -> 0.48333233 | E48: =CORREL(crimesUSA[T_MENACE],crimesUSA[T_AGRESSION_PHYSIQUE]) -> 0.49414002 | F48: =CORREL(crimesUSA[T_MEURTRE],crimesUSA[T_AGRESSION_PHYSIQUE]) -> 0.58768936 | G48: =CORREL(crimesUSA[T_VIOL],crimesUSA[T_AGRESSION_PHYSIQUE]) -> 0.071607331 | H48: =CORREL(crimesUSA[T_AGRESSION_PHYSIQUE],crimesUSA[T_AGRESSION_PHYSIQUE]) -> 1
A50: Matrice de Variance-Covariance
B52: CAMBRIOLAGE | C52: VOL | D52: VOL_AUTO | E52: MENACE | F52: MEURTRE | G52: VIOL | H52: AGRESSION_PHYSIQUE
A53: CAMBRIOLAGE | B53: =_xlfn.COVARIANCE.P(crimesUSA[T_CAMBRIOLAGE],crimesUSA[T_CAMBRIOLAGE]) -> 19868.42 | C53: =_xlfn.COVARIANCE.P(crimesUSA[T_VOL],crimesUSA[T_CAMBRIOLAGE]) -> 37818.366 | D53: =_xlfn.COVARIANCE.P(crimesUSA[T_VOL_AUTO],crimesUSA[T_CAMBRIOLAGE]) -> 9503.3849 | E53: =_xlfn.COVARIANCE.P(crimesUSA[T_MENACE],crimesUSA[T_CAMBRIOLAGE]) -> 11377.319 | F53: =_xlfn.COVARIANCE.P(crimesUSA[T_MEURTRE],crimesUSA[T_CAMBRIOLAGE]) -> 259.30051 | G53: =_xlfn.COVARIANCE.P(crimesUSA[T_VIOL],crimesUSA[T_CAMBRIOLAGE]) -> 836.39193 | H53: =_xlfn.COVARIANCE.P(crimesUSA[T_AGRESSION_PHYSIQUE],crimesUSA[T_CAMBRIOLAGE]) -> 1748.9341
A54: VOL | B54: =_xlfn.COVARIANCE.P(crimesUSA[T_CAMBRIOLAGE],crimesUSA[T_VOL]) -> 37818.366 | C54: =_xlfn.COVARIANCE.P(crimesUSA[T_VOL],crimesUSA[T_VOL]) -> 132017.01 | D54: =_xlfn.COVARIANCE.P(crimesUSA[T_VOL_AUTO],crimesUSA[T_VOL]) -> 27147.931 | E54: =_xlfn.COVARIANCE.P(crimesUSA[T_MENACE],crimesUSA[T_VOL]) -> 26554.243 | F54: =_xlfn.COVARIANCE.P(crimesUSA[T_MEURTRE],crimesUSA[T_VOL]) -> 557.44343 | G54: =_xlfn.COVARIANCE.P(crimesUSA[T_VIOL],crimesUSA[T_VOL]) -> 2439.7142 | H54: =_xlfn.COVARIANCE.P(crimesUSA[T_AGRESSION_PHYSIQUE],crimesUSA[T_VOL]) -> 5373.9749
A55: VOL_AUTO | B55: =_xlfn.COVARIANCE.P(crimesUSA[T_CAMBRIOLAGE],crimesUSA[T_VOL_AUTO]) -> 9503.3849 | C55: =_xlfn.COVARIANCE.P(crimesUSA[T_VOL],crimesUSA[T_VOL_AUTO]) -> 27147.931 | D55: =_xlfn.COVARIANCE.P(crimesUSA[T_VOL_AUTO],crimesUSA[T_VOL_AUTO]) -> 9213.2013 | E55: =_xlfn.COVARIANCE.P(crimesUSA[T_MENACE],crimesUSA[T_VOL_AUTO]) -> 6521.7235 | F55: =_xlfn.COVARIANCE.P(crimesUSA[T_MEURTRE],crimesUSA[T_VOL_AUTO]) -> 97.26266 | G55: =_xlfn.COVARIANCE.P(crimesUSA[T_VIOL],crimesUSA[T_VOL_AUTO]) -> 832.20724 | H55: =_xlfn.COVARIANCE.P(crimesUSA[T_AGRESSION_PHYSIQUE],crimesUSA[T_VOL]) -> 5373.9749
A56: MENACE | B56: =_xlfn.COVARIANCE.P(crimesUSA[T_CAMBRIOLAGE],crimesUSA[T_MENACE]) -> 11377.319 | C56: =_xlfn.COVARIANCE.P(crimesUSA[T_VOL],crimesUSA[T_MENACE]) -> 26554.243 | D56: =_xlfn.COVARIANCE.P(crimesUSA[T_VOL_AUTO],crimesUSA[T_MENACE]) -> 6521.7235 | E56: =_xlfn.COVARIANCE.P(crimesUSA[T_MENACE],crimesUSA[T_MENACE]) -> 14145.143 | F56: =_xlfn.COVARIANCE.P(crimesUSA[T_MEURTRE],crimesUSA[T_MENACE]) -> 204.62069 | G56: =_xlfn.COVARIANCE.P(crimesUSA[T_VIOL],crimesUSA[T_MENACE]) -> 1276.2717 | H56: =_xlfn.COVARIANCE.P(crimesUSA[T_AGRESSION_PHYSIQUE],crimesUSA[T_MENACE]) -> 1880.8967
A57: MEURTRE | B57: =_xlfn.COVARIANCE.P(crimesUSA[T_CAMBRIOLAGE],crimesUSA[T_MEURTRE]) -> 259.30051 | C57: =_xlfn.COVARIANCE.P(crimesUSA[T_VOL],crimesUSA[T_MEURTRE]) -> 557.44343 | D57: =_xlfn.COVARIANCE.P(crimesUSA[T_VOL_AUTO],crimesUSA[T_MEURTRE]) -> 97.26266 | E57: =_xlfn.COVARIANCE.P(crimesUSA[T_MENACE],crimesUSA[T_MEURTRE]) -> 204.62069 | F57: =_xlfn.COVARIANCE.P(crimesUSA[T_MEURTRE],crimesUSA[T_MEURTRE]) -> 6.804916 | G57: =_xlfn.COVARIANCE.P(crimesUSA[T_VIOL],crimesUSA[T_MEURTRE]) -> 8.600904 | H57: =_xlfn.COVARIANCE.P(crimesUSA[T_AGRESSION_PHYSIQUE],crimesUSA[T_MEURTRE]) -> 49.064848
A58: VIOL | B58: =_xlfn.COVARIANCE.P(crimesUSA[T_CAMBRIOLAGE],crimesUSA[T_VIOL]) -> 836.39193 | C58: =_xlfn.COVARIANCE.P(crimesUSA[T_VOL],crimesUSA[T_VIOL]) -> 2439.7142 | D58: =_xlfn.COVARIANCE.P(crimesUSA[T_VOL_AUTO],crimesUSA[TOTAL_VIOL]) -> 46084.202 | E58: =_xlfn.COVARIANCE.P(crimesUSA[T_MENACE],crimesUSA[T_VIOL]) -> 1276.2717 | F58: =_xlfn.COVARIANCE.P(crimesUSA[T_MEURTRE],crimesUSA[T_VIOL]) -> 8.600904 | G58: =_xlfn.COVARIANCE.P(crimesUSA[T_VIOL],crimesUSA[T_VIOL]) -> 385.57858 | H58: =_xlfn.COVARIANCE.P(crimesUSA[T_AGRESSION_PHYSIQUE],crimesUSA[T_VIOL]) -> 45.001312
A59: AGRESSION_PHYSIQUE | B59: =_xlfn.COVARIANCE.P(crimesUSA[T_CAMBRIOLAGE],crimesUSA[T_AGRESSION_PHYSIQUE]) -> 1748.9341 | C59: =_xlfn.COVARIANCE.P(crimesUSA[T_VOL],crimesUSA[T_AGRESSION_PHYSIQUE]) -> 5373.9749 | D59: =_xlfn.COVARIANCE.P(crimesUSA[T_VOL_AUTO],crimesUSA[T_AGRESSION_PHYSIQUE]) -> 1484.7809 | E59: =_xlfn.COVARIANCE.P(crimesUSA[T_MENACE],crimesUSA[T_AGRESSION_PHYSIQUE]) -> 1880.8967 | F59: =_xlfn.COVARIANCE.P(crimesUSA[T_MEURTRE],crimesUSA[T_AGRESSION_PHYSIQUE]) -> 49.064848 | G59: =_xlfn.COVARIANCE.P(crimesUSA[T_VIOL],crimesUSA[T_AGRESSION_PHYSIQUE]) -> 45.001312 | H59: =_xlfn.COVARIANCE.P(crimesUSA[T_AGRESSION_PHYSIQUE],crimesUSA[T_AGRESSION_PHYSIQUE]) -> 1024.2889
...

Sheet Centrées-réduites
A1: Données Centrées-réduites :
A3: ETAT | B3: T_CAMBRIOLAGE | C3: T_VOL | D3: T_VOL_AUTO | E3: T_MENACE | F3: T_MEURTRE | G3: T_VIOL | H3: T_AGRESSION_PHYSIQUE
A4: ALASKA | B4: =('crimesUSA'!E2-'Données brutes'!K$13) / 'Données brutes'!K$15 -> 0.99183159 | C4: =('crimesUSA'!F2-'Données brutes'!L$13) / 'Données brutes'!L$15 -> 1.457428 | D4: =('crimesUSA'!G2-'Données brutes'!M$13) / 'Données brutes'!M$15 -> 1.5082499 | E4: =('crimesUSA'!I2-'Données brutes'!N$13) / 'Données brutes'!N$15 -> 2.9049546 | F4: =('crimesUSA'!J2-'Données brutes'!O$13) / 'Données brutes'!O$15 -> 1.7718157 | G4: =('crimesUSA'!K2-'Données brutes'!P$13) / 'Données brutes'!P$15 -> 5.1470362 | H4: =('crimesUSA'!L2-'Données brutes'!Q$13) / 'Données brutes'!Q$15 -> 1.5721532
A5: ALABAMA | B5: =('crimesUSA'!E3-'Données brutes'!K$13) / 'Données brutes'!K$15 -> 1.3096627 | C5: =('crimesUSA'!F3-'Données brutes'!L$13) / 'Données brutes'!L$15 -> 0.96230143 | D5: =('crimesUSA'!G3-'Données brutes'!M$13) / 'Données brutes'!M$15 -> 0.4539231 | E5: =('crimesUSA'!I3-'Données brutes'!N$13) / 'Données brutes'!N$15 -> 1.0972195 | F5: =('crimesUSA'!J3-'Données brutes'!O$13) / 'Données brutes'!O$15 -> 0.96679345 | G5: =('crimesUSA'!K3-'Données brutes'!P$13) / 'Données brutes'!P$15 -> -0.27663257 | H5: =('crimesUSA'!L3-'Données brutes'!Q$13) / 'Données brutes'!Q$15 -> 0.55667147
A6: ARKANSAS | B6: =('crimesUSA'!E4-'Données brutes'!K$13) / 'Données brutes'!K$15 -> 1.7899565 | C6: =('crimesUSA'!F4-'Données brutes'!L$13) / 'Données brutes'!L$15 -> 1.3104588 | D6: =('crimesUSA'!G4-'Données brutes'!M$13) / 'Données brutes'!M$15 -> 0.34348966 | E6: =('crimesUSA'!I4-'Données brutes'!N$13) / 'Données brutes'!N$15 -> 1.6588786 | F6: =('crimesUSA'!J4-'Données brutes'!O$13) / 'Données brutes'!O$15 -> 1.2351342 | G6: =('crimesUSA'!K4-'Données brutes'!P$13) / 'Données brutes'!P$15 -> 1.5057938 | H6: =('crimesUSA'!L4-'Données brutes'!Q$13) / 'Données brutes'!Q$15 -> -0.34320158
A7: ARIZONA | B7: =('crimesUSA'!E5-'Données brutes'!K$13) / 'Données brutes'!K$15 -> 0.33346723 | C7: =('crimesUSA'!F5-'Données brutes'!L$13) / 'Données brutes'!L$15 -> 0.71680233 | D7: =('crimesUSA'!G5-'Données brutes'!M$13) / 'Données brutes'!M$15 -> 0.37995353 | E7: =('crimesUSA'!I5-'Données brutes'!N$13) / 'Données brutes'!N$15 -> 0.51622188 | F7: =('crimesUSA'!J5-'Données brutes'!O$13) / 'Données brutes'!O$15 -> 0.085102357 | G7: =('crimesUSA'!K5-'Données brutes'!P$13) / 'Données brutes'!P$15 -> 0.13587182 | H7: =('crimesUSA'!L5-'Données brutes'!Q$13) / 'Données brutes'!Q$15 -> 0.79726253
A8: CALIFORNIA | B8: =('crimesUSA'!E6-'Données brutes'!K$13) / 'Données brutes'!K$15 -> 0.27529279 | C8: =('crimesUSA'!F6-'Données brutes'!L$13) / 'Données brutes'!L$15 -> 0.13718226 | D8: =('crimesUSA'!G6-'Données brutes'!M$13) / 'Données brutes'!M$15 -> 1.5197099 | E8: =('crimesUSA'!I6-'Données brutes'!N$13) / 'Données brutes'!N$15 -> 0.13954033 | F8: =('crimesUSA'!J6-'Données brutes'!O$13) / 'Données brutes'!O$15 -> -0.18323841 | G8: =('crimesUSA'!K6-'Données brutes'!P$13) / 'Données brutes'!P$15 -> -0.51598697 | H8: =('crimesUSA'!L6-'Données brutes'!Q$13) / 'Données brutes'!Q$15 -> 2.1814423
A9: COLORADO | B9: =('crimesUSA'!E7-'Données brutes'!K$13) / 'Données brutes'!K$15 -> 0.0078322657 | C9: =('crimesUSA'!F7-'Données brutes'!L$13) / 'Données brutes'!L$15 -> 0.88578938 | D9: =('crimesUSA'!G7-'Données brutes'!M$13) / 'Données brutes'!M$15 -> 1.7822498 | E9: =('crimesUSA'!I7-'Données brutes'!N$13) / 'Données brutes'!N$15 -> -0.035347527 | F9: =('crimesUSA'!J7-'Données brutes'!O$13) / 'Données brutes'!O$15 -> -0.37491038 | G9: =('crimesUSA'!K7-'Données brutes'!P$13) / 'Données brutes'!P$15 -> 0.99652912 | H9: =('crimesUSA'!L7-'Données brutes'!Q$13) / 'Données brutes'!Q$15 -> 0.031745521
A10: CONNECTICUT | B10: =('crimesUSA'!E8-'Données brutes'!K$13) / 'Données brutes'!K$15 -> -1.1819059 | C10: =('crimesUSA'!F8-'Données brutes'!L$13) / 'Données brutes'!L$15 -> -1.2598507 | D10: =('crimesUSA'!G8-'Données brutes'!M$13) / 'Données brutes'!M$15 -> -0.47538469 | E10: =('crimesUSA'!I8-'Données brutes'!N$13) / 'Données brutes'!N$15 -> -1.2234079 | F10: =('crimesUSA'!J8-'Données brutes'!O$13) / 'Données brutes'!O$15 -> -0.71991994 | G10: =('crimesUSA'!K8-'Données brutes'!P$13) / 'Données brutes'!P$15 -> -1.3257178 | H10: =('crimesUSA'!L8-'Données brutes'!Q$13) / 'Données brutes'!Q$15 -> -0.2650876
A11: DELAWARE | B11: =('crimesUSA'!E9-'Données brutes'!K$13) / 'Données brutes'!K$15 -> -0.30148547 | C11: =('crimesUSA'!F9-'Données brutes'!L$13) / 'Données brutes'!L$15 -> 0.67772064 | D11: =('crimesUSA'!G9-'Données brutes'!M$13) / 'Données brutes'!M$15 -> -0.50247213 | E11: =('crimesUSA'!I9-'Données brutes'!N$13) / 'Données brutes'!N$15 -> 0.45568378 | F11: =('crimesUSA'!J9-'Données brutes'!O$13) / 'Données brutes'!O$15 -> 0.046767962 | G11: =('crimesUSA'!K9-'Données brutes'!P$13) / 'Données brutes'!P$15 -> -0.80626783 | H11: =('crimesUSA'!L9-'Données brutes'!Q$13) / 'Données brutes'!Q$15 -> 0.57854338
A12: FLORIDA | B12: =('crimesUSA'!E10-'Données brutes'!K$13) / 'Données brutes'!K$15 -> -0.36959213 | C12: =('crimesUSA'!F10-'Données brutes'!L$13) / 'Données brutes'!L$15 -> 0.36396618 | D12: =('crimesUSA'!G10-'Données brutes'!M$13) / 'Données brutes'!M$15 -> -0.32432008 | E12: =('crimesUSA'!I10-'Données brutes'!N$13) / 'Données brutes'!N$15 -> 0.065549316 | F12: =('crimesUSA'!J10-'Données brutes'!O$13) / 'Données brutes'!O$15 -> 0.16177115 | G12: =('crimesUSA'!K10-'Données brutes'!P$13) / 'Données brutes'!P$15 -> -0.41922668 | H12: =('crimesUSA'!L10-'Données brutes'!Q$13) / 'Données brutes'!Q$15 -> 0.40356807
A13: GEORGIA | B13: =('crimesUSA'!E11-'Données brutes'!K$13) / 'Données brutes'!K$15 -> 0.17597058 | C13: =('crimesUSA'!F11-'Données brutes'!L$13) / 'Données brutes'!L$15 -> 0.66973916 | D13: =('crimesUSA'!G11-'Données brutes'!M$13) / 'Données brutes'!M$15 -> 0.11428819 | E13: =('crimesUSA'!I11-'Données brutes'!N$13) / 'Données brutes'!N$15 -> -0.15558293 | F13: =('crimesUSA'!J11-'Données brutes'!O$13) / 'Données brutes'!O$15 -> 0.5451151 | G13: =('crimesUSA'!K11-'Données brutes'!P$13) / 'Données brutes'!P$15 -> -1.0252516 | H13: =('crimesUSA'!L11-'Données brutes'!Q$13) / 'Données brutes'!Q$15 -> 0.38794527
A14: HAWAI | B14: =('crimesUSA'!E12-'Données brutes'!K$13) / 'Données brutes'!K$15 -> 0.21215224 | C14: =('crimesUSA'!F12-'Données brutes'!L$13) / 'Données brutes'!L$15 -> 1.5317382 | D14: =('crimesUSA'!G12-'Données brutes'!M$13) / 'Données brutes'!M$15 -> 1.6478544 | E14: =('crimesUSA'!I12-'Données brutes'!N$13) / 'Données brutes'!N$15 -> -0.86017922 | F14: =('crimesUSA'!J12-'Données brutes'!O$13) / 'Données brutes'!O$15 -> -0.52824797 | G14: =('crimesUSA'!K12-'Données brutes'!P$13) / 'Données brutes'!P$15 -> 0.32429975 | H14: =('crimesUSA'!L12-'Données brutes'!Q$13) / 'Données brutes'!Q$15 -> 0.54104867
A15: IOWA | B15: =('crimesUSA'!E13-'Données brutes'!K$13) / 'Données brutes'!K$15 -> 0.16887613 | C15: =('crimesUSA'!F13-'Données brutes'!L$13) / 'Données brutes'!L$15 -> -0.92710589 | D15: =('crimesUSA'!G13-'Données brutes'!M$13) / 'Données brutes'!M$15 -> -0.52018316 | E15: =('crimesUSA'!I13-'Données brutes'!N$13) / 'Données brutes'!N$15 -> -0.42127795 | F15: =('crimesUSA'!J13-'Données brutes'!O$13) / 'Données brutes'!O$15 -> -1.1032639 | G15: =('crimesUSA'!K13-'Données brutes'!P$13) / 'Données brutes'!P$15 -> -0.54654285 | H15: =('crimesUSA'!L13-'Données brutes'!Q$13) / 'Données brutes'!Q$15 -> -1.0993449
... A53: WYOMING | B53: =('crimesUSA'!E51-'Données brutes'!K$13) / 'Données brutes'!K$15 -> -0.75269208 | C53: =('crimesUSA'!F51-'Données brutes'!L$13) / 'Données brutes'!L$15 -> -0.90756504 | D53: =('crimesUSA'!G51-'Données brutes'!M$13) / 'Données brutes'!M$15 -> -0.93482945 | E53: =('crimesUSA'!I51-'Données brutes'!N$13) / 'Données brutes'!N$15 -> -0.86522406 | F53: =('crimesUSA'!J51-'Données brutes'!O$13) / 'Données brutes'!O$15 -> -0.98826071 | G53: =('crimesUSA'!K51-'Données brutes'!P$13) / 'Données brutes'!P$15 -> 0.42615268 | H53: =('crimesUSA'!L51-'Données brutes'!Q$13) / 'Données brutes'!Q$15 -> -1.5930253

Sheet Calculs
A2: Matrice de Variance-Covariance des données centrées-réduites
B4: CAMBRIOLAGE | C4: VOL | D4: VOL_AUTO | E4: MENACE | F4: MEURTRE | G4: VIOL | H4: AGRESSION_PHYSIQUE
A5: CAMBRIOLAGE | B5: =_xlfn.COVARIANCE.P('Centrées-réduites'!$B4:$B53,'Centrées-réduites'!B4:B53) -> 1 | C5: =_xlfn.COVARIANCE.P('Centrées-réduites'!$B4:$B53,'Centrées-réduites'!C4:C53) -> 0.73842458 | D5: =_xlfn.COVARIANCE.P('Centrées-réduites'!$B4:$B53,'Centrées-réduites'!D4:D53) -> 0.70241112 | E5: =_xlfn.COVARIANCE.P('Centrées-réduites'!$B4:$B53,'Centrées-réduites'!E4:E53) -> 0.67866369 | F5: =_xlfn.COVARIANCE.P('Centrées-réduites'!$B4:$B53,'Centrées-réduites'!F4:F53) -> 0.70519679 | G5: =_xlfn.COVARIANCE.P('Centrées-réduites'!$B4:$B53,'Centrées-réduites'!G4:G53) -> 0.30218418 | H5: =_xlfn.COVARIANCE.P('Centrées-réduites'!$B4:$B53,'Centrées-réduites'!H4:H53) -> 0.38768639
A6: VOL | B6: =_xlfn.COVARIANCE.P('Centrées-réduites'!$C4:$C53,'Centrées-réduites'!B4:B53) -> 0.73842458 | C6: =_xlfn.COVARIANCE.P('Centrées-réduites'!$C4:$C53,'Centrées-réduites'!C4:C53) -> 1 | D6: =_xlfn.COVARIANCE.P('Centrées-réduites'!$C4:$C53,'Centrées-réduites'!D4:D53) -> 0.77842451 | E6: =_xlfn.COVARIANCE.P('Centrées-réduites'!$C4:$C53,'Centrées-réduites'!E4:E53) -> 0.61449069 | F6: =_xlfn.COVARIANCE.P('Centrées-réduites'!$C4:$C53,'Centrées-réduites'!F4:F53) -> 0.58813154 | G6: =_xlfn.COVARIANCE.P('Centrées-réduites'!$C4:$C53,'Centrées-réduites'!G4:G53) -> 0.3419539 | H6: =_xlfn.COVARIANCE.P('Centrées-réduites'!$C4:$C53,'Centrées-réduites'!H4:H53) -> 0.46213562
A7: VOL_AUTO | B7: =_xlfn.COVARIANCE.P('Centrées-réduites'!$D4:$D53,'Centrées-réduites'!B4:B53) -> 0.70241112 | C7: =_xlfn.COVARIANCE.P('Centrées-réduites'!$D4:$D53,'Centrées-réduites'!C4:C53) -> 0.77842451 | D7: =_xlfn.COVARIANCE.P('Centrées-réduites'!$D4:$D53,'Centrées-réduites'!D4:D53) -> 1 | E7: =_xlfn.COVARIANCE.P('Centrées-réduites'!$D4:$D53,'Centrées-réduites'!E4:E53) -> 0.5712858 | F7: =_xlfn.COVARIANCE.P('Centrées-réduites'!$D4:$D53,'Centrées-réduites'!F4:F53) -> 0.38844495 | G7: =_xlfn.COVARIANCE.P('Centrées-réduites'!$D4:$D53,'Centrées-réduites'!G4:G53) -> 0.4415397 | H7: =_xlfn.COVARIANCE.P('Centrées-réduites'!$D4:$D53,'Centrées-réduites'!H4:H53) -> 0.48333233
A8: MENACE | B8: =_xlfn.COVARIANCE.P('Centrées-réduites'!$E4:$E53,'Centrées-réduites'!B4:B53) -> 0.67866369 | C8: =_xlfn.COVARIANCE.P('Centrées-réduites'!$E4:$E53,'Centrées-réduites'!C4:C53) -> 0.61449069 | D8: =_xlfn.COVARIANCE.P('Centrées-réduites'!$E4:$E53,'Centrées-réduites'!D4:D53) -> 0.5712858 | E8: =_xlfn.COVARIANCE.P('Centrées-réduites'!$E4:$E53,'Centrées-réduites'!E4:E53) -> 1 | F8: =_xlfn.COVARIANCE.P('Centrées-réduites'!$E4:$E53,'Centrées-réduites'!F4:F53) -> 0.6595299 | G8: =_xlfn.COVARIANCE.P('Centrées-réduites'!$E4:$E53,'Centrées-réduites'!G4:G53) -> 0.546491 | H8: =_xlfn.COVARIANCE.P('Centrées-réduites'!$E4:$E53,'Centrées-réduites'!H4:H53) -> 0.49414002
A9: MEURTRE | B9: =_xlfn.COVARIANCE.P('Centrées-réduites'!$F4:$F53,'Centrées-réduites'!B4:B53) -> 0.70519679 | C9: =_xlfn.COVARIANCE.P('Centrées-réduites'!$F4:$F53,'Centrées-réduites'!C4:C53) -> 0.58813154 | D9: =_xlfn.COVARIANCE.P('Centrées-réduites'!$F4:$F53,'Centrées-réduites'!D4:D53) -> 0.38844495 | E9: =_xlfn.COVARIANCE.P('Centrées-réduites'!$F4:$F53,'Centrées-réduites'!E4:E53) -> 0.6595299 | F9: =_xlfn.COVARIANCE.P('Centrées-réduites'!$F4:$F53,'Centrées-réduites'!F4:F53) -> 1 | G9: =_xlfn.COVARIANCE.P('Centrées-réduites'!$F4:$F53,'Centrées-réduites'!G4:G53) -> 0.16790989 | H9: =_xlfn.COVARIANCE.P('Centrées-réduites'!$F4:$F53,'Centrées-réduites'!H4:H53) -> 0.58768936
A10: VIOL | B10: =_xlfn.COVARIANCE.P('Centrées-réduites'!$G4:$G53,'Centrées-réduites'!B4:B53) -> 0.30218418 | C10: =_xlfn.COVARIANCE.P('Centrées-réduites'!$G4:$G53,'Centrées-réduites'!C4:C53) -> 0.3419539 | D10: =_xlfn.COVARIANCE.P('Centrées-réduites'!$G4:$G53,'Centrées-réduites'!D4:D53) -> 0.4415397 | E10: =_xlfn.COVARIANCE.P('Centrées-réduites'!$G4:$G53,'Centrées-réduites'!E4:E53) -> 0.546491 | F10: =_xlfn.COVARIANCE.P('Centrées-réduites'!$G4:$G53,'Centrées-réduites'!F4:F53) -> 0.16790989 | G10: =_xlfn.COVARIANCE.P('Centrées-réduites'!$G4:$G53,'Centrées-réduites'!G4:G53) -> 1 | H10: =_xlfn.COVARIANCE.P('Centrées-réduites'!$G4:$G53,'Centrées-réduites'!H4:H53) -> 0.071607331
A11: AGRESSION_PHYSIQUE | B11: =_xlfn.COVARIANCE.P('Centrées-réduites'!$H4:$H53,'Centrées-réduites'!B4:B53) -> 0.38768639 | C11: =_xlfn.COVARIANCE.P('Centrées-réduites'!$H4:$H53,'Centrées-réduites'!C4:C53) -> 0.46213562 | D11: =_xlfn.COVARIANCE.P('Centrées-réduites'!$H4:$H53,'Centrées-réduites'!D4:D53) -> 0.48333233 | E11: =_xlfn.COVARIANCE.P('Centrées-réduites'!$H4:$H53,'Centrées-réduites'!E4:E53) -> 0.49414002 | F11: =_xlfn.COVARIANCE.P('Centrées-réduites'!$H4:$H53,'Centrées-réduites'!F4:F53) -> 0.58768936 | G11: =_xlfn.COVARIANCE.P('Centrées-réduites'!$H4:$H53,'Centrées-réduites'!G4:G53) -> 0.071607331 | H11: =_xlfn.COVARIANCE.P('Centrées-réduites'!$H4:$H53,'Centrées-réduites'!H4:H53) -> 1
A13: Inertie du nuage de points centré-réduit: | E13: =7 -> 7
B17: distance(i ; 0)
A18: ALASKA | B18: =SQRT(SUMSQ('Centrées-réduites'!B4:H4)) -> 6.7767532
A19: ALABAMA | B19: =SQRT(SUMSQ('Centrées-réduites'!B5:H5)) -> 2.317817
A20: ARKANSAS | B20: =SQRT(SUMSQ('Centrées-réduites'!B6:H6)) -> 3.4207994
A21: ARIZONA | B21: =SQRT(SUMSQ('Centrées-réduites'!B7:H7)) -> 1.3027612
A22: CALIFORNIA | B22: =SQRT(SUMSQ('Centrées-réduites'!B8:H8)) -> 2.7353435
A23: COLORADO | B23: =SQRT(SUMSQ('Centrées-réduites'!B9:H9)) -> 2.2576501
A24: CONNECTICUT | B24: =SQRT(SUMSQ('Centrées-réduites'!B10:H10)) -> 2.6557347
A25: DELAWARE | B25: =SQRT(SUMSQ('Centrées-réduites'!B11:H11)) -> 1.4132559
A26: FLORIDA | B26: =SQRT(SUMSQ('Centrées-réduites'!B12:H12)) -> 0.86217055
A27: GEORGIA | B27: =SQRT(SUMSQ('Centrées-réduites'!B13:H13)) -> 1.4197102
A28: HAWAI | B28: =SQRT(SUMSQ('Centrées-réduites'!B14:H14)) -> 2.5541169
A29: IOWA | B29: =SQRT(SUMSQ('Centrées-réduites'!B15:H15)) -> 2.0150855
... A67: WYOMING | B67: =SQRT(SUMSQ('Centrées-réduites'!B53:H53)) -> 2.5901223
A70: Inertie = | B70: =SUMSQ(B18:B67)/COUNT(B17:B67) -> 7
A74: Calcul de F1(Alaska) = | B74: {=MMULT('Centrées-réduites'!B4:H4, E75:E81)} -> 5.2780002
E75: 0.425
A76: ici, vous êtes libre de | E76: 0.423
A77: détailler le calcul | E77: 0.403
A78: comme vous le | E78: 0.417
A79: souhaitez | E79: 0.382
E80: 0.242
E81: 0.317
