Workbook
Name amort_stat_restantes: 'Validation décisions'!$Z$38
Name an: Décisions!$I$2
Name an_debut: Paramètres!$E$30:$F$35
Name capac_station: Paramètres!$B$21
Name capac_tot_stations: 'Validation décisions'!$Z$43
Name cout_comp: Paramètres!$F$3:$K$4
Name déc_offre: Décisions!$B$6:$F$11
Name durée_amort: Paramètres!$B$20
Name liste_niveau: Paramètres!$E$7:$E$10
Name liste_temps: Paramètres!$E$20:$E$23
Name Max_com_ext: Paramètres!$C$59
Name Max_com_int: Paramètres!$C$58
Name Max_form_A: Paramètres!$C$57
Name Max_form_T: Paramètres!#REF!
Name Max_form_T: Paramètres!#REF!
Name Max_ind_Cons: Paramètres!$C$56
Name Max_ind_Tech: Paramètres!$C$55
Name Min_ind_Cons: Paramètres!$B$56
Name Min_ind_Tech: Paramètres!$B$55
Name Px_achat_station: Paramètres!$B$18
Name Px_cession_station: Paramètres!$B$19
Name tab_niveau: Paramètres!$E$6:$K$10
Name tab_temps: Paramètres!$E$19:$K$23
Name tab_usure: Paramètres!$E$40:$F$49
Name val_nette_stat_cedees: 'Validation décisions'!$Z$47

Sheet Décisions
D1: FICHE DE DECISIONS
B2: Univers | D2: Entreprise n° : | F2: 1 | H2: Année : | I2: 7
A4: Définition de l'offre commerciale
B5: Prix de vente (€) | C5: Pub ciblée produit (€) | D5: Qualité des composants | E5: Temps | F5: Nb prestations prévues | G5: CA prévi
A6: Réinstallation PC | B6: 135 | C6: 1000 | D6: améliorée | E6: long | F6: 1200 | G6: =+F6*B6 -> 162000
A7: Assemblage PC | B7: 1350 | C7: 3000 | D7: luxe | E7: long | F7: 120 | G7: =+F7*B7 -> 162000
A8: Formation particulier | B8: 375 | C8: 2000 | E8: long | F8: 300 | G8: =+F8*B8 -> 112500 | H8: =SUM(G6:G11) -> 1239000
A9: Pack "réseau" | B9: 3500 | C9: 4000 | D9: améliorée | E9: court | F9: 150 | G9: =+F9*B9 -> 525000
A10: Pack "site internet" | B10: 2700 | C10: 1000 | D10: luxe | E10: long | F10: 25 | G10: =+F10*B10 -> 67500
A11: Développement d'applications | B11: 14000 | C11: 5000 | D11: améliorée | E11: long | F11: 15 | G11: =+F11*B11 -> 210000
A13: Gestion du personnel
C14: Recrutement / Licenciement (+/-) | F14: Indice de salaire (base 100) | I14: Budget formation (€)
A15: Techniciens / développeurs | C15: 2 | F15: 120 | I15: 25000 | J15: €
A16: Conseillers (accueil) | C16: 1 | F16: 117 | I16: 10000 | J16: €
A18: Communication | F18: Etudes de marché
A19: Budget interne (accueil) | C19: 20000 | D19: € | F19: Prix | H19: Image de marque
A20: Budget externe (publicité) | C20: 45000 | D20: € | F20: Publicité | H20: Entreprise
F21: Parts de marché | H21: Questionnaire
A22: Gestion des immobilisations | F22: Volume prévisionnel | H22: sensibilisation client
A23: Achat / Cession de stations de travail (+/-) | C23: 2 | F23: Satisfaction des clients
A24: Remplacement de stations de travail | C24: 1 | F24: Fidélisation des clients
F25: Liasse fiscale | G25: x
A26: Finances
A27: Demande d'emprunt (€) | C27: €
A28: Placements (+/-) | C28: €
A29: Augmentation de capital | C29: €
A31: Rappel des données de la fin de la période précédente | F31: Historique des stations
A32: Nb total Techniciens / développeurs | B32: 4 | F32: Période | G32: 1 | H32: =IF(an>COLUMN(H33)-6,COLUMN(H33)-6,"") -> 2 | I32: 3 | J32: 4 | K32: 5 | L32: 6 | M32: 7 | N32: =IF(an>COLUMN(N33)-6,COLUMN(N33)-6,"") | O32: =IF(an>COLUMN(O33)-6,COLUMN(O33)-6,"")
A33: Nb total Conseillers | B33: 2 | F33: Nb stations achetées | G33: 2 | H33: 1 | I33: 0 | J33: 1 | K33: 0 | L33: 2 | M33: 2
F34: Nb stations vendues | H34: 0 | I34: 0 | J34: 1 | K34: 0 | L34: 2 | M34: 1
A37: Données à reprendre dans le dernier bilan :
A38: Actif | D38: Passif
A39: Amortissement des stations | B39: 18400 | C39: € | D39: Capital | G39: €
A40: Placements | C40: € | D40: Réserves | G40: €
D41: Résultat de l'exercice | F41: 15893 | G41: €
D42: Emprunts | G42: €
D43: Concours bancaire | F43: 51528 | G43: €
A45: Données à reprendre dans les tableaux d'amortissement des emprunts
A46: Annuités d'emprunts | C46: €
A48: Donnée à calculer :
...

Sheet Validation décisions
B1: Erreurs sur la feuille de décisions | J1: Intermédiaires de calcul
A3: =IF(an="","Remplir le n° de l'année","") | J3: 1 | K3: 2 | L3: 3 | M3: 4 | N3: 5 | O3: 6 | P3: Total
I4: Prix de vente (€) | J4: {=TRANSPOSE(Décisions!B6:B11)} -> 135 | K4: 1350 | L4: 375 | M4: 3500 | N4: 2700 | O4: 14000
A5: Prestations | I5: Budget Niveau | J5: {=TRANSPOSE(Décisions!D6:D11)} -> améliorée | K5: luxe | L5: 0 | M5: améliorée | N5: luxe | O5: améliorée
A6: Réinstallation PC | B6: =ROW(A6)-5 -> 1 | C6: =VLOOKUP(B6,an_debut,2) -> 1 | D6: =IF(AND(C6>an,Décisions!B6>0),"Prestation inexistante à cette date","") | I6: Temps | J6: {=TRANSPOSE(Décisions!E6:E11)} -> long | K6: long | L6: long | M6: court | N6: long | O6: long
A7: Assemblage PC | B7: =ROW(A7)-5 -> 2 | C7: =VLOOKUP(B7,an_debut,2) -> 2 | D7: =IF(AND(C7>an,Décisions!B7>0),"Prestation inexistante à cette date","") | I7: Nb prestations prévues | J7: {=TRANSPOSE(Décisions!F6:F11)} -> 1200 | K7: 120 | L7: 300 | M7: 150 | N7: 25 | O7: 15
A8: Formation particulier | B8: =ROW(A8)-5 -> 3 | C8: =VLOOKUP(B8,an_debut,2) -> 3 | D8: =IF(AND(C8>an,Décisions!B8>0),"Prestation inexistante à cette date","") | I8: Promo produit | J8: {=TRANSPOSE(Décisions!C6:C11)} -> 1000 | K8: 3000 | L8: 2000 | M8: 4000 | N8: 1000 | O8: 5000 | P8: =SUM(J8:O8) -> 16000
A9: Pack "réseau" | B9: =ROW(A9)-5 -> 4 | C9: =VLOOKUP(B9,an_debut,2) -> 1 | D9: =IF(AND(C9>an,Décisions!B9>0),"Prestation inexistante à cette date","")
A10: Pack "site internet" | B10: =ROW(A10)-5 -> 5 | C10: =VLOOKUP(B10,an_debut,2) -> 4 | D10: =IF(AND(C10>an,Décisions!B10>0),"Prestation inexistante à cette date","") | I10: Prix | J10: =Paramètres!B4 -> 1000 | K10: =IF(Décisions!G19="x",1,0) -> 0
A11: Développement d'applications | B11: =ROW(A11)-5 -> 6 | C11: =VLOOKUP(B11,an_debut,2) -> 5 | D11: =IF(AND(C11>an,Décisions!B11>0),"Prestation inexistante à cette date","") | I11: Publicité | J11: =Paramètres!B5 -> 1000 | K11: =IF(Décisions!G20="x",1,0) -> 0
I12: Parts de marché | J12: =Paramètres!B6 -> 1000 | K12: =IF(Décisions!G21="x",1,0) -> 0
A13: Nb total de prestations | B13: =SUM(Décisions!F6:F11) -> 1810 | D13: =IF(B13>$B$15,"Risque de dépassement à l'accueil","") | I13: Image de marque | J13: =Paramètres!B7 -> 1000 | K13: =IF(Décisions!I19="x",1,0) -> 0
A14: Conseillers | B14: =Décisions!B33+Décisions!C16 -> 3 | D14: =IF(B13>B16,"Dépassement de capacité à l'accueil","") | I14: Entreprise | J14: =Paramètres!B8 -> 2000 | K14: =IF(Décisions!I20="x",1,0) -> 0
A15: Capacité prestations standard | B15: =$B$14*Paramètres!$B$32 -> 3000 | I15: Questionnaire | J15: =Paramètres!B9 -> 1500 | K15: =IF(Décisions!I21="x",1,0) -> 0
A16: Capacité prestations maxi | B16: =$B$14*Paramètres!$B$32*(1+Paramètres!B52) -> 3900 | I16: Volume prévisionnel | J16: =Paramètres!B10 -> 2000 | K16: =IF(Décisions!G22="x",1,0) -> 0
I17: Satisfaction de la clientèle | J17: =Paramètres!B11 -> 1000 | K17: =IF(Décisions!G23="x",1,0) -> 0
A18: Temps de réparation | I18: Fidélisation de la clientèle | J18: =Paramètres!B12 -> 1000 | K18: =IF(Décisions!G24="x",1,0) -> 0
A19: Réinstallation PC | B19: =Décisions!E6 -> long | C19: =Paramètres!$F$17*VLOOKUP(B19,tab_temps,2,FALSE)*Décisions!F6/100 -> 2160 | I19: Liasse fiscale | J19: =Paramètres!B13 -> 1000 | K19: =IF(Décisions!G25="x",1,0) -> 1
A20: Assemblage PC | B20: =Décisions!E7 -> long | C20: =Paramètres!$G$17*VLOOKUP(B20,tab_temps,3,FALSE)*Décisions!F7/100 -> 576 | I20: sensibilisation client | J20: =Paramètres!B14 -> 1000 | K20: =IF(Décisions!I22="x",1,0) -> 0
A21: Formation particulier | B21: =Décisions!E8 -> long | C21: =Paramètres!$H$17*VLOOKUP(B21,tab_temps,4,FALSE)*Décisions!F8/100 -> 2160
A22: Pack "réseau" | B22: =Décisions!E9 -> court | C22: =Paramètres!$I$17*VLOOKUP(B22,tab_temps,5,FALSE)*Décisions!F9/100 -> 2250 | I22: Embauche
A23: Pack "site internet" | B23: =Décisions!E10 -> long | C23: =Paramètres!$J$17*VLOOKUP(B23,tab_temps,6,FALSE)*Décisions!F10/100 -> 720 | I23: Techniciens / développeurs | J23: =IF(Décisions!$C$15>0,Décisions!$C$15,0) -> 2 | K23: =J23*Paramètres!$B$38 -> 2000
A24: Développement d'applications | B24: =Décisions!E11 -> long | C24: =Paramètres!$K$17*VLOOKUP(B24,tab_temps,7,FALSE)*Décisions!F11/100 -> 1800 | I24: Conseillers (accueil) | J24: =IF(Décisions!$C$16>0,Décisions!$C$16,0) -> 1 | K24: =J24*Paramètres!$B$37 -> 1300
A25: Total | C25: =SUM(C19:C24) -> 9666 | I25: Licenciement
A26: Techniciens | B26: =Décisions!B32+Décisions!C15 -> 6 | D26: =(IF(C25>B27,"Risque de dépassement des heures technicien","")) -> Risque de dépassement des heures technicien | I26: Techniciens / développeurs | J26: =IF(Décisions!$C$15<0,-Décisions!$C$15,0) -> 0 | K26: =J26*Paramètres!$B$41 -> 0
A27: Capacité techniciens standard | B27: =$B$26*Paramètres!$B$33 -> 7200 | D27: =IF(C25>B28,"Dépassement des heures techniciens","") -> Dépassement des heures techniciens | I27: Conseillers (accueil) | J27: =IF(Décisions!$C$16<0,-Décisions!$C$16,0) -> 0 | K27: =J27*Paramètres!$B$40 -> 0
A28: Capacité techniciens maxi | B28: =$B$26*Paramètres!$B$33*(1+Paramètres!B53) -> 9360 | I28: Coût embauche-licenciement | K28: =SUM(K23:K27) -> 3300
A30: Nb de stations | B30: =$Z$37 -> 5 | D30: =IF(C25>B31, "Nb de stations insuffisant","")
A31: Capacité stations | B31: =capac_tot_stations -> 10000
A32: Nb de stations cédées | B32: =$Z$45 -> 1 | D32: =IF($Z$35>$Z$34-HLOOKUP(an,$Q$33:$Y$34,2,FALSE),"Décision incohérente","") | P32: =Décisions!F31 -> Historique des stations
P33: =Décisions!F32 -> Période | Q33: 1 | R33: 2 | S33: 3 | T33: 4 | U33: 5 | V33: 6 | W33: 7 | X33: 8 | Y33: 9 | Z33: Total
P34: Achat | Q34: =IF(Q33<an,Décisions!G33,IF(Q33=an,MAX(0,Décisions!$C$23)+Décisions!$C$24,0)) -> 2 | R34: =IF(R33<an,Décisions!H33,IF(R33=an,MAX(0,Décisions!$C$23)+Décisions!$C$24,0)) -> 1 | S34: =IF(S33<an,Décisions!I33,IF(S33=an,MAX(0,Décisions!$C$23)+Décisions!$C$24,0)) -> 0 | T34: =IF(T33<an,Décisions!J33,IF(T33=an,MAX(0,Décisions!$C$23)+Décisions!$C$24,0)) -> 1 | U34: =IF(U33<an,Décisions!K33,IF(U33=an,MAX(0,Décisions!$C$23)+Décisions!$C$24,0)) -> 0 | V34: =IF(V33<an,Décisions!L33,IF(V33=an,MAX(0,Décisions!$C$23)+Décisions!$C$24,0)) -> 2 | W34: =IF(W33<an,Décisions!M33,IF(W33=an,MAX(0,Décisions!$C$23)+Décisions!$C$24,0)) -> 3 | X34: =IF(X33<an,Décisions!N33,IF(X33=an,MAX(0,Décisions!$C$23)+Décisions!$C$24,0)) -> 0 | Y34: =IF(Y33<an,Décisions!O33,IF(Y33=an,MAX(0,Décisions!$C$23)+Décisions!$C$24,0)) -> 0 | Z34: =SUM(Q34:Y34) -> 9
A35: Placements | B35: =Décisions!B40+Décisions!B28 -> 0 | D35: =IF(B35<0, "Décison incohérente","") | P35: Ventes | Q35: =IF(Q33<an,Décisions!G34,IF(Q33=an,MAX(0,-Décisions!$C$23)+Décisions!$C$24,0)) -> 0 | R35: =IF(R33<an,Décisions!H34,IF(R33=an,MAX(0,-Décisions!$C$23)+Décisions!$C$24,0)) -> 0 | S35: =IF(S33<an,Décisions!I34,IF(S33=an,MAX(0,-Décisions!$C$23)+Décisions!$C$24,0)) -> 0 | T35: =IF(T33<an,Décisions!J34,IF(T33=an,MAX(0,-Décisions!$C$23)+Décisions!$C$24,0)) -> 1 | U35: =IF(U33<an,Décisions!K34,IF(U33=an,MAX(0,-Décisions!$C$23)+Décisions!$C$24,0)) -> 0 | V35: =IF(V33<an,Décisions!L34,IF(V33=an,MAX(0,-Décisions!$C$23)+Décisions!$C$24,0)) -> 2 | W35: =IF(W33<an,Décisions!M34,IF(W33=an,MAX(0,-Décisions!$C$23)+Décisions!$C$24,0)) -> 1 | X35: =IF(X33<an,Décisions!N34,IF(X33=an,MAX(0,-Décisions!$C$23)+Décisions!$C$24,0)) -> 0 | Y35: =IF(Y33<an,Décisions!O34,IF(Y33=an,MAX(0,-Décisions!$C$23)+Décisions!$C$24,0)) -> 0 | Z35: =SUM(Q35:Y35) -> 4
P36: Tx amort. Début pér. | Q36: =IF(Q33<=an,MIN((an-Q33)/durée_amort,1),"") -> 1 | R36: =IF(R33<=an,MIN((an-R33)/durée_amort,1),"") -> 1 | S36: =IF(S33<=an,MIN((an-S33)/durée_amort,1),"") -> 0.8 | T36: =IF(T33<=an,MIN((an-T33)/durée_amort,1),"") -> 0.6 | U36: =IF(U33<=an,MIN((an-U33)/durée_amort,1),"") -> 0.4 | V36: =IF(V33<=an,MIN((an-V33)/durée_amort,1),"") -> 0.2 | W36: =IF(W33<=an,MIN((an-W33)/durée_amort,1),"") -> 0 | X36: =IF(X33<=an,MIN((an-X33)/durée_amort,1),"") | ... Z36: =IF(Z33<=an,MIN((an-Z33)/durée_amort,1),"")
P37: Nb stations restantes | Q37: =MAX(0,Q34-Z35) -> 0 | R37: =MAX(0,R34-Q39) -> 0 | S37: =MAX(0,S34-R39) -> 0 | T37: =MAX(0,T34-S39) -> 0 | U37: =MAX(0,U34-T39) -> 0 | V37: =MAX(0,V34-U39) -> 2 | W37: =MAX(0,W34-V39) -> 3 | X37: =MAX(0,X34-W39) -> 0 | Y37: =MAX(0,Y34-X39) -> 0 | Z37: =SUM(Q37:Y37) -> 5
P38: Amortissement des stations restantes-bilan fin pér | Q38: =IF(Q33<=an,MIN(1,Q36+1/durée_amort)*Px_achat_station*Q37,"") -> 0 | R38: =IF(R33<=an,MIN(1,R36+1/durée_amort)*Px_achat_station*R37,"") -> 0 | S38: =IF(S33<=an,MIN(1,S36+1/durée_amort)*Px_achat_station*S37,"") -> 0 | T38: =IF(T33<=an,MIN(1,T36+1/durée_amort)*Px_achat_station*T37,"") -> 0 | U38: =IF(U33<=an,MIN(1,U36+1/durée_amort)*Px_achat_station*U37,"") -> 0 | V38: =IF(V33<=an,MIN(1,V36+1/durée_amort)*Px_achat_station*V37,"") -> 16000 | W38: =IF(W33<=an,MIN(1,W36+1/durée_amort)*Px_achat_station*W37,"") -> 12000 | X38: =IF(X33<=an,MIN(1,X36+1/durée_amort)*Px_achat_station*X37,"") | Y38: =IF(Y33<=an,MIN(1,Y36+1/durée_amort)*Px_achat_station*Y37,"") | Z38: =SUM(Q38:Y38) -> 28000
P39: Solde | Q39: =MAX(0,$Z$35-Q34) -> 2 | R39: =MAX(0,Q39-R34) -> 1 | S39: =MAX(0,R39-S34) -> 1 | T39: =MAX(0,S39-T34) -> 0 | U39: =MAX(0,T39-U34) -> 0 | V39: =MAX(0,U39-V34) -> 0 | W39: =MAX(0,V39-W34) -> 0 | X39: =MAX(0,W39-X34) -> 0 | Y39: =MAX(0,X39-Y34) -> 0 | Z39: =MAX(0,Y39-Z34) -> 0
P40: Nb vendu datant de pér | Q40: =Q34-Q37 -> 2 | R40: =R34-R37 -> 1 | S40: =S34-S37 -> 0 | T40: =T34-T37 -> 1 | U40: =U34-U37 -> 0 | V40: =V34-V37 -> 0 | W40: =W34-W37 -> 0 | X40: =X34-X37 -> 0 | Y40: =Y34-Y37 -> 0
P41: Cumul nb vendu datant pér | Q41: =Q40 -> 2 | R41: =Q41+R40 -> 3 | S41: =R41+S40 -> 3 | T41: =S41+T40 -> 4 | U41: =T41+U40 -> 4 | V41: =U41+V40 -> 4 | W41: =V41+W40 -> 4 | X41: =W41+X40 -> 4 | Y41: =X41+Y40 -> 4
P42: Tx usure stations | Q42: =IF(Q33<=an,VLOOKUP(an-Q33,tab_usure,2,FALSE),"") -> 0 | R42: =IF(R33<=an,VLOOKUP(an-R33,tab_usure,2,FALSE),"") -> 0 | S42: =IF(S33<=an,VLOOKUP(an-S33,tab_usure,2,FALSE),"") -> 0.7 | T42: =IF(T33<=an,VLOOKUP(an-T33,tab_usure,2,FALSE),"") -> 0.8 | U42: =IF(U33<=an,VLOOKUP(an-U33,tab_usure,2,FALSE),"") -> 0.9 | V42: =IF(V33<=an,VLOOKUP(an-V33,tab_usure,2,FALSE),"") -> 1 | W42: =IF(W33<=an,VLOOKUP(an-W33,tab_usure,2,FALSE),"") -> 1 | X42: =IF(X33<=an,VLOOKUP(an-X33,tab_usure,2,FALSE),"") | ... Z42: =IF(Z33<=an,VLOOKUP(an-Z33,tab_usure,2,FALSE),"")
...

Sheet  Compte de Résultats
A1: Terstrat | B1: Univers | C1: =Décisions!$C$2 -> 0 | D1: Entreprise | E1: =Décisions!$F$2 -> 1 | G1: An | H1: =an -> 7
A3: Attention ! | B3: Résultat prévisionnel, sous l'hypothèse que toutes les prestations ont été réalisées
A5: Produits d'exploitation | B5: Total | C5: 1 | D5: 2 | E5: 3 | F5: 4 | G5: 5 | H5: 6
A6: Ventes | B6: =SUM(C6:H6) -> 1239000 | C6: ='Validation décisions'!J4*'Validation décisions'!J7 -> 162000 | D6: ='Validation décisions'!K4*'Validation décisions'!K7 -> 162000 | E6: ='Validation décisions'!L4*'Validation décisions'!L7 -> 112500 | F6: ='Validation décisions'!M4*'Validation décisions'!M7 -> 525000 | G6: ='Validation décisions'!N4*'Validation décisions'!N7 -> 67500 | H6: ='Validation décisions'!O4*'Validation décisions'!O7 -> 210000
A7: Autres produits d'exploitation | B7: =SUM(C7:H7) -> 0
A8: Total des produits | B8: =SUM(C8:H8) -> 1239000 | C8: =C6+C7 -> 162000 | D8: =D6+D7 -> 162000 | E8: =E6+E7 -> 112500 | F8: =F6+F7 -> 525000 | G8: =G6+G7 -> 67500 | H8: =H6+H7 -> 210000
A9: Charges d'exploitation
A10: Achats de consommables | B10: =SUM(C10:H10) -> 493800 | C10: =ROUND('Validation décisions'!J7*HLOOKUP('Validation décisions'!J3,cout_comp,2,)*VLOOKUP('Validation décisions'!J5,tab_niveau,Paramètres!F3+1,)/100,0) -> 28800 | D10: =ROUND('Validation décisions'!K7*HLOOKUP('Validation décisions'!K3,cout_comp,2,)*VLOOKUP('Validation décisions'!K5,tab_niveau,Paramètres!G3+1,)/100,0) -> 84000 | E10: =ROUND('Validation décisions'!L7*HLOOKUP('Validation décisions'!L3,cout_comp,2,)*VLOOKUP('Validation décisions'!L5,tab_niveau,Paramètres!H3+1,)/100,0) -> 0 | F10: =ROUND('Validation décisions'!M7*HLOOKUP('Validation décisions'!M3,cout_comp,2,)*VLOOKUP('Validation décisions'!M5,tab_niveau,Paramètres!I3+1,)/100,0) -> 270000 | G10: =ROUND('Validation décisions'!N7*HLOOKUP('Validation décisions'!N3,cout_comp,2,)*VLOOKUP('Validation décisions'!N5,tab_niveau,Paramètres!J3+1,)/100,0) -> 21000 | H10: =ROUND('Validation décisions'!O7*HLOOKUP('Validation décisions'!O3,cout_comp,2,)*VLOOKUP('Validation décisions'!O5,tab_niveau,Paramètres!K3+1,)/100,0) -> 90000
A11: Charges externes
A12: Entretien des bancs | B12: =Paramètres!$B$17*'Validation décisions'!$B$30 -> 10000
A13: Communication | B13: =Décisions!$C$19+Décisions!$C$20+'Validation décisions'!$P$8 -> 81000
A14: Formation | B14: =Décisions!$I$15+Décisions!$I$16 -> 35000
A15: Etudes | B15: =SUMPRODUCT('Validation décisions'!J10:J20,'Validation décisions'!K10:K20) -> 1000 | D15: DONT LIASSE FISCALE et….
A16: Total | B16: =SUM(B12:B15) -> 127000
A17: Personnel
A18: Personnel technique | B18: ='Validation décisions'!$B$26*Paramètres!$B$35*Décisions!F15/100 -> 226800
A19: Personnel d'accueil | B19: ='Validation décisions'!$B$14*Paramètres!$B$34*Décisions!F16/100 -> 81081
A20: Total | B20: =SUM(B18:B19) -> 307881
A21: Dotations aux amortissements | B21: ='Validation décisions'!$B$30*Paramètres!$B$18/Paramètres!$B$20 -> 20000
A22: Total des charges | B22: =B21+B20+B16+B10 -> 948681
A23: Résultat d'exploitation | B23: =B8-B22 -> 290319
A24: Produits financiers | B24: ='Validation décisions'!$B$35*Paramètres!$B$49 -> 0
A25: Charges financières | B25: =Décisions!$F$43*Paramètres!$B$46+(Décisions!$F$42+Décisions!$B$27)*Paramètres!$B$47 -> 5152.8
A26: Résultat financier | B26: =B24-B25 -> -5152.8
A27: Produits exceptionnels | B27: =Px_cession_station*(MAX(0,-Décisions!$C$23)+Décisions!$C$24) -> 2000
A28: Charges exceptionnelles | B28: =val_nette_stat_cedees+'Validation décisions'!$K$28 -> 11300
A29: Résultat exceptionnel | B29: =B27-B28 -> -9300
A30: Résultat avant impôts | B30: =B8-B22+B26+B29 -> 275866.2
A31: Impôts | B31: =IF(B30<Décisions!$B$49,0,ROUND(($B$30-Décisions!$B$49)*Paramètres!$B$45,0)) -> 68967
A32: Résultat | B32: =B30-B31 -> 206899.2

Sheet Bilan
A1: Terstrat | B1: Univers | C1: =Décisions!$C$2 -> 0 | D1: Entreprise | E1: =Décisions!$F$2 -> 1
C2: An | D2: =an -> 7
A4: Attention ! | B4: Bilan prévisionnel, sous l'hypothèse que toutes les prestations ont été réalisées
A5: Actif | C5: Passif
A6: Actif immobilisé | C6: Capitaux propres | J6: =B11+B13 -> 72000
A7: Stations de travail | C7: Capital | D7: =Décisions!$F$39+Décisions!$B$29 -> 0 | J7: =D10+D12+D13 -> 291759.2
A8: Brut | B8: =Px_achat_station*'Validation décisions'!$Z$37 -> 100000 | C8: Réserves | D8: =Décisions!$F$40+Décisions!$F$41 -> 15893
A9: Amortissement | B9: =amort_stat_restantes -> 28000 | C9: Résultat de l'exercice | D9: =' Compte de Résultats'!$B$32 -> 206899.2
A10: Net | B10: =B8-B9 -> 72000 | C10: Total capitaux propres | D10: =SUM(D7:D9) -> 222792.2
A11: Total actif immobilisé | B11: =B10 -> 72000 | C11: Dettes
A12: Actif circulant | C12: Emprunts à long et moyen terme | D12: =Décisions!$F$42-Décisions!$B$46+Décisions!$F$42*Paramètres!$B$47+Emprunts!$F$9 -> 0
A13: Placements | B13: =Décisions!$B$28 -> 0 | C13: Dettes fiscales | D13: =' Compte de Résultats'!$B$31 -> 68967
A14: Disponibilités | B14: =IF(J7>J6,J7-J6,0) -> 219759.2 | C14: Concours bancaires | D14: =IF(J6>J7,J6-J7,0) -> 0
A15: Total actif circulant | B15: =B13+B14 -> 219759.2 | C15: Total dettes | D15: =SUM(D12:D14) -> 68967
A16: TOTAL ACTIF | B16: =B11+B15 -> 291759.2 | C16: TOTAL PASSIF | D16: =D10+D15 -> 291759.2

Sheet Emprunts
A1: Tableau d'amortissement d'un emprunt à annuités constantes
A3: Demande d'emprunt (€) | B3: =Décisions!$B$27 -> 0 | D3: Taux d'intérêt | E3: =Paramètres!$B$47 -> 0.06
D4: Durée | E4: =Paramètres!$B$48 -> 5
A6: Annuité | B6: =ROUND(-PMT($E$3,E4,B3),2) -> 0
A8: An | B8: Valeur initiale | C8: Annuité | D8: Intérêt | E8: Amortissement | F8: Valeur finale
A9: 1 | B9: =B3 -> 0 | C9: =$B$6 -> 0 | D9: =ROUND($E$3*B9,2) -> 0 | E9: =C9-D9 -> 0 | F9: =B9-E9 -> 0
A10: 2 | B10: =F9 -> 0 | C10: =$B$6 -> 0 | D10: =ROUND($E$3*B10,2) -> 0 | E10: =C10-D10 -> 0 | F10: =B10-E10 -> 0
A11: 3 | B11: =F10 -> 0 | C11: =$B$6 -> 0 | D11: =ROUND($E$3*B11,2) -> 0 | E11: =C11-D11 -> 0 | F11: =B11-E11 -> 0
A12: 4 | B12: =F11 -> 0 | C12: =$B$6 -> 0 | D12: =ROUND($E$3*B12,2) -> 0 | E12: =C12-D12 -> 0 | F12: =B12-E12 -> 0
A13: 5 | B13: =F12 -> 0 | C13: =$B$6 -> 0 | D13: =ROUND($E$3*B13,2) -> 0 | E13: =C13-D13 -> 0 | F13: =B13-E13 -> 0

Sheet Marge nette d'expl. 
A1: Terstrat | B1: Univers | C1: =Décisions!$C$2 -> 0 | D1: Entreprise | E1: =Décisions!$F$2 -> 1 | G1: An | H1: =an -> 7
A3: Attention ! | B3: Marge prévisionnelle, sous l'hypothèse que toutes les prestations ont été réalisées
B5: 1 | C5: 2 | D5: 3 | E5: 4 | F5: 5 | G5: 6 | J5: Total | K5: 1 | L5: 2 | M5: 3 | N5: 4 | O5: 5 | P5: 6
A6: Prix de vente | B6: ='Validation décisions'!J4 -> 135 | C6: ='Validation décisions'!K4 -> 1350 | D6: ='Validation décisions'!L4 -> 375 | E6: ='Validation décisions'!M4 -> 3500 | F6: ='Validation décisions'!N4 -> 2700 | G6: ='Validation décisions'!O4 -> 14000 | I6: Nb prestations prévues | J6: =SUM(K6:P6) -> 1810 | K6: ='Validation décisions'!J7 -> 1200 | L6: ='Validation décisions'!K7 -> 120 | M6: ='Validation décisions'!L7 -> 300 | N6: ='Validation décisions'!M7 -> 150 | O6: ='Validation décisions'!N7 -> 25 | P6: ='Validation décisions'!O7 -> 15
A8: Charges directes (composants) | B8: =IF(B6>0,Paramètres!F4*VLOOKUP('Validation décisions'!J5,tab_niveau,B5+1,)/100,"") -> 24 | C8: =IF(C6>0,Paramètres!G4*VLOOKUP('Validation décisions'!K5,tab_niveau,C5+1,)/100,"") -> 700 | D8: =IF(D6>0,Paramètres!H4*VLOOKUP('Validation décisions'!L5,tab_niveau,D5+1,)/100,"") -> 0 | E8: =IF(E6>0,Paramètres!I4*VLOOKUP('Validation décisions'!M5,tab_niveau,E5+1,)/100,"") -> 1800 | F8: =IF(F6>0,Paramètres!J4*VLOOKUP('Validation décisions'!N5,tab_niveau,F5+1,)/100,"") -> 840 | G8: =IF(G6>0,Paramètres!K4*VLOOKUP('Validation décisions'!O5,tab_niveau,G5+1,)/100,"") -> 6000 | I8: Charges indirectes
A9: Charges directes (promo) | B9: =IF(B6>0,'Validation décisions'!J8/K6,"") -> 0.83333333 | C9: =IF(C6>0,'Validation décisions'!K8/L6,"") -> 25 | D9: =IF(D6>0,'Validation décisions'!L8/M6,"") -> 6.6666667 | E9: =IF(E6>0,'Validation décisions'!M8/N6,"") -> 26.666667 | F9: =IF(F6>0,'Validation décisions'!N8/O6,"") -> 40 | G9: =IF(G6>0,'Validation décisions'!O8/P6,"") -> 333.33333 | I9: Relatives à l'accueil
A10: Relatives à l'accueil | B10: =IF(B6>0,$J$14/$J$6,"") -> 50.320994 | C10: =IF(C6>0,$J$14/$J$6,"") -> 50.320994 | D10: =IF(D6>0,$J$14/$J$6,"") -> 50.320994 | E10: =IF(E6>0,$J$14/$J$6,"") -> 50.320994 | F10: =IF(F6>0,$J$14/$J$6,"") -> 50.320994 | G10: =IF(G6>0,$J$14/$J$6,"") -> 50.320994 | I10: Clé de répartition | J10: Nb prestations
A11: Relatives à la réparation | B11: =IF(B6>0,K21/K6,"") -> 46.89013 | C11: =IF(C6>0,L21/L6,"") -> 125.04035 | D11: =IF(D6>0,M21/M6,"") -> 187.56052 | E11: =IF(E6>0,N21/N6,"") -> 390.75109 | F11: =IF(F6>0,O21/O6,"") -> 750.24209 | G11: =IF(G6>0,P21/P6,"") -> 3126.0087 | I11: % | J11: =SUM(K11:P11) -> 1 | K11: =K6/$J$6 -> 0.66298343 | L11: =L6/$J$6 -> 0.066298343 | M11: =M6/$J$6 -> 0.16574586 | N11: =N6/$J$6 -> 0.082872928 | O11: =O6/$J$6 -> 0.013812155 | P11: =P6/$J$6 -> 0.0082872928
A12: Relatives aux stations | B12: =IF(B6>0,K27/K6,"") -> 5.5865922 | C12: =IF(C6>0,L27/L6,"") -> 14.897579 | D12: =IF(D6>0,M27/M6,"") -> 22.346369 | E12: =IF(E6>0,N27/N6,"") -> 46.554935 | F12: =IF(F6>0,O27/O6,"") -> 89.385475 | G12: =IF(G6>0,P27/P6,"") -> 372.43948 | I12: Salaires | J12: =' Compte de Résultats'!$B$19 -> 81081
A13: Relatives à la structure | B13: =IF(B6>0,K35/K6,"") -> 7.1912833 | C13: =IF(C6>0,L35/L6,"") -> 71.912833 | D13: =IF(D6>0,M35/M6,"") -> 19.975787 | E13: =IF(E6>0,N35/N6,"") -> 186.44068 | F13: =IF(F6>0,O35/O6,"") -> 143.82567 | G13: =IF(G6>0,P35/P6,"") -> 745.76271 | I13: Formation | J13: =Décisions!$I$16 -> 10000
I14: Total | J14: =SUM(J12:J13) -> 91081
A15: Coût de Revient global | B15: =IF(B6>0,B8+B9+B10+B11+B12+B13,"") -> 134.82233 | C15: =IF(C6>0,C8+C9+C10+C11+C12+C13,"") -> 987.17175 | D15: =IF(D6>0,D8+D9+D10+D11+D12+D13,"") -> 286.87034 | E15: =IF(E6>0,E8+E9+E10+E11+E12+E13,"") -> 2500.7344 | F15: =IF(F6>0,F8+F9+F10+F11+F12+F13,"") -> 1913.7742 | G15: =IF(G6>0,G8+G9+G10+G11+G12+G13,"") -> 10627.865 | I15: Relatives à la réparation
I16: Clé de répartition | J16: Temps en réparation
A17: Marge nette d'exploitation | B17: =IF(B6>0,B6-B15,"") -> 0.17766637 | C17: =IF(C6>0,C6-C15,"") -> 362.82825 | D17: =IF(D6>0,D6-D15,"") -> 88.129662 | E17: =IF(E6>0,E6-E15,"") -> 999.26564 | F17: =IF(F6>0,F6-F15,"") -> 786.22578 | G17: =IF(G6>0,G6-G15,"") -> 3372.1348 | I17: Temps en réparation Total | J17: =SUM(K17:P17) -> 9666 | K17: =K6*Paramètres!F17*VLOOKUP('Validation décisions'!J6,tab_temps,'Marge nette d''expl. '!K5+1,)/100 -> 2160 | L17: =L6*Paramètres!G17*VLOOKUP('Validation décisions'!K6,tab_temps,'Marge nette d''expl. '!L5+1,)/100 -> 576 | M17: =M6*Paramètres!H17*VLOOKUP('Validation décisions'!L6,tab_temps,'Marge nette d''expl. '!M5+1,)/100 -> 2160 | N17: =N6*Paramètres!I17*VLOOKUP('Validation décisions'!M6,tab_temps,'Marge nette d''expl. '!N5+1,)/100 -> 2250 | O17: =O6*Paramètres!J17*VLOOKUP('Validation décisions'!N6,tab_temps,'Marge nette d''expl. '!O5+1,)/100 -> 720 | P17: =P6*Paramètres!K17*VLOOKUP('Validation décisions'!O6,tab_temps,'Marge nette d''expl. '!P5+1,)/100 -> 1800
A18: en % du prix de vente | B18: =IF(B6>0,B17/B6,"") -> 0.0013160472 | C18: =IF(C6>0,C17/C6,"") -> 0.26876166 | D18: =IF(D6>0,D17/D6,"") -> 0.23501243 | E18: =IF(E6>0,E17/E6,"") -> 0.28550447 | F18: =IF(F6>0,F17/F6,"") -> 0.29119473 | G18: =IF(G6>0,G17/G6,"") -> 0.24086677 | I18: % | J18: =SUM(K18:P18) -> 1 | K18: =K17/$J$17 -> 0.22346369 | L18: =L17/$J$17 -> 0.059590317 | M18: =M17/$J$17 -> 0.22346369 | N18: =N17/$J$17 -> 0.23277467 | O18: =O17/$J$17 -> 0.074487896 | P18: =P17/$J$17 -> 0.18621974
I19: Salaires | J19: =' Compte de Résultats'!$B$18 -> 226800
I20: Formation | J20: =Décisions!$I$15 -> 25000
A21: Décomposition des charges (en %) | I21: Total | J21: =SUM(J19:J20) -> 251800 | K21: =$J$21*K18 -> 56268.156 | L21: =$J$21*L18 -> 15004.842 | M21: =$J$21*M18 -> 56268.156 | N21: =$J$21*N18 -> 58612.663 | O21: =$J$21*O18 -> 18756.052 | P21: =$J$21*P18 -> 46890.13
A22: Charges directes (composants) | B22: =IF(B$6>0,B8/B$15,"") -> 0.17801205 | C22: =IF(C$6>0,C8/C$15,"") -> 0.70909646 | D22: =IF(D$6>0,D8/D$15,"") -> 0 | E22: =IF(E$6>0,E8/E$15,"") -> 0.71978857 | F22: =IF(F$6>0,F8/F$15,"") -> 0.43892325 | G22: =IF(G$6>0,G8/G$15,"") -> 0.56455364 | I22: Relatives aux stations
A23: Charges directes (promo) | B23: =IF(B$6>0,B9/B$15,"") -> 0.006180974 | C23: =IF(C$6>0,C9/C$15,"") -> 0.025324874 | D23: =IF(D$6>0,D9/D$15,"") -> 0.023239303 | E23: =IF(E$6>0,E9/E$15,"") -> 0.010663534 | F23: =IF(F$6>0,F9/F$15,"") -> 0.020901107 | G23: =IF(G$6>0,G9/G$15,"") -> 0.031364091 | I23: Clé de répartition | J23: Temps en réparation
A24: Relatives à l'accueil | B24: =IF(B$6>0,B10/B$15,"") -> 0.37323931 | C24: =IF(C$6>0,C10/C$15,"") -> 0.050974913 | D24: =IF(D$6>0,D10/D$15,"") -> 0.17541372 | E24: =IF(E$6>0,E10/E$15,"") -> 0.020122487 | F24: =IF(F$6>0,F10/F$15,"") -> 0.026294112 | G24: =IF(G$6>0,G10/G$15,"") -> 0.0047348168 | I24: % | J24: =J18 -> 1 | K24: =K18 -> 0.22346369 | L24: =L18 -> 0.059590317 | M24: =M18 -> 0.22346369 | N24: =N18 -> 0.23277467 | O24: =O18 -> 0.074487896 | P24: =P18 -> 0.18621974
A25: Relatives à la réparation | B25: =IF(B$6>0,B11/B$15,"") -> 0.34779201 | C25: =IF(C$6>0,C11/C$15,"") -> 0.12666524 | D25: =IF(D$6>0,D11/D$15,"") -> 0.65381636 | E25: =IF(E$6>0,E11/E$15,"") -> 0.15625454 | F25: =IF(F$6>0,F11/F$15,"") -> 0.39202226 | G25: =IF(G$6>0,G11/G$15,"") -> 0.29413326 | I25: Entretien des stations | J25: =' Compte de Résultats'!$B$12 -> 10000
A26: Relatives aux stations | B26: =IF(B$6>0,B12/B$15,"") -> 0.041436697 | C26: =IF(C$6>0,C12/C$15,"") -> 0.015091172 | D26: =IF(D$6>0,D12/D$15,"") -> 0.077897105 | E26: =IF(E$6>0,E12/E$15,"") -> 0.018616505 | F26: =IF(F$6>0,F12/F$15,"") -> 0.046706385 | G26: =IF(G$6>0,G12/G$15,"") -> 0.035043677 | I26: Amortissement des stations | J26: =' Compte de Résultats'!B21 -> 20000
A27: Relatives à la structure | B27: =IF(B$6>0,B13/B$15,"") -> 0.053338962 | C27: =IF(C$6>0,C13/C$15,"") -> 0.072847336 | D27: =IF(D$6>0,D13/D$15,"") -> 0.069633504 | E27: =IF(E$6>0,E13/E$15,"") -> 0.074554371 | F27: =IF(F$6>0,F13/F$15,"") -> 0.075152891 | G27: =IF(G$6>0,G13/G$15,"") -> 0.070170509 | I27: Total | J27: =SUM(J25:J26) -> 30000 | K27: =$J$27*K24 -> 6703.9106 | L27: =$J$27*L24 -> 1787.7095 | M27: =$J$27*M24 -> 6703.9106 | N27: =$J$27*N24 -> 6983.2402 | O27: =$J$27*O24 -> 2234.6369 | P27: =$J$27*P24 -> 5586.5922
I28: Relatives à la structure
I29: Clé de répartition | J29: CA
A30: Les produits et charges financiers et exceptionnels ne sont pas pris en compte. | I30: CA total | J30: =SUM(K30:P30) -> 1239000 | K30: =K6*B6 -> 162000 | L30: =L6*C6 -> 162000 | M30: =M6*D6 -> 112500 | N30: =N6*E6 -> 525000 | O30: =O6*F6 -> 67500 | P30: =P6*G6 -> 210000
I31: % | J31: =SUM(K31:P31) -> 1 | K31: =K30/$J$30 -> 0.13075061 | L31: =L30/$J$30 -> 0.13075061 | M31: =M30/$J$30 -> 0.090799031 | N31: =N30/$J$30 -> 0.42372881 | O31: =O30/$J$30 -> 0.054479419 | P31: =P30/$J$30 -> 0.16949153
I32: Communication interne | J32: =Décisions!$C$19 -> 20000
I33: Communication externe | J33: =Décisions!$C$20 -> 45000
I34: Etudes | J34: =' Compte de Résultats'!$B$15 -> 1000
I35: Total | J35: =SUM(J32:J34) -> 66000 | K35: =$J$35*K31 -> 8629.54 | L35: =$J$35*L31 -> 8629.54 | M35: =$J$35*M31 -> 5992.7361 | N35: =$J$35*N31 -> 27966.102 | O35: =$J$35*O31 -> 3595.6416 | P35: =$J$35*P31 -> 11186.441

Sheet Paramètres
A1: Paramètres généraux | E1: Paramètres prestations
E2: Prestation | F2: Réinstallation PC | G2: Assembage Pc | I2: Pack "Réseau"
A3: Etudes de marché | E3: Qualité des composants | F3: 1 | G3: 2 | H3: 3 | I3: 4 | J3: 5 | K3: 6
A4: Prix | B4: 1000 | E4: Coût indice 100 | F4: 20 | G4: 500 | H4: 0 | I4: 1500 | J4: 600 | K4: 5000
A5: Publicité | B5: 1000 | E5: Niveau
A6: Parts de marché | B6: 1000 | E6: 0
A7: Image de marque | B7: 1000 | E7: discount | F7: 60 | G7: 60 | H7: 60 | I7: 60 | J7: 60 | K7: 60
A8: Entreprise | B8: 2000 | E8: standard | F8: 80 | G8: 80 | H8: 80 | I8: 80 | J8: 80 | K8: 80
A9: Questionnaire | B9: 1500 | E9: améliorée | F9: 120 | G9: 120 | H9: 120 | I9: 120 | J9: 120 | K9: 120
A10: Volume prévisionnel | B10: 2000 | E10: luxe | F10: 140 | G10: 140 | H10: 140 | I10: 140 | J10: 140 | K10: 140
A11: Satisfaction de la clientèle | B11: 1000
A12: Fidélisation de la clientèle | B12: 1000
A13: Liasse fiscale | B13: 1000
A14: sensibilisation des clients | B14: 1000
A16: Stations de travail | E16: Temps de réparation
A17: Coût annuel d'entretien | B17: 2000 | E17: Temps indice 100 | F17: 1.5 | G17: 4 | H17: 6 | I17: 15 | J17: 24 | K17: 100
A18: Investissement | B18: 20000 | E18: Niveau de temps
A19: Cession | B19: 2000 | E19: 0
A20: Durée d'amortissement | B20: 5 | E20: très court | F20: 70 | G20: 70 | H20: 70 | I20: 70 | J20: 70 | K20: 70
A21: Capacité d'une station | B21: 2000 | E21: court | F21: 100 | G21: 100 | H21: 100 | I21: 100 | J21: 100 | K21: 100
A22: Amortissement technique des stations | E22: long | F22: 120 | G22: 120 | H22: 120 | I22: 120 | J22: 120 | K22: 120
A23: Année achat | B23: 1 | E23: très long | F23: 150 | G23: 150 | H23: 150 | I23: 150 | J23: 150 | K23: 150
A24: Année +1 | B24: 1
A25: Année +2 | B25: 0.9
A26: Année +3 | B26: 0.8
A27: Année +4 | B27: 0.7
A28: Année +5 et plus | B28: 0
E29: Scenario | F29: An début
E30: 1 | F30: 1
A31: Personnel | E31: 2 | F31: 2
A32: Capacité d'accueil | B32: 1000 | E32: 3 | F32: 3
A33: Capacité de réparation | B33: 1200 | E33: 4 | F33: 1
A34: Salaire du personnel d'accueil | B34: =22000*1.05 -> 23100 | E34: 5 | F34: 4
A35: Salaire du personnel technique | B35: =30000*1.05 -> 31500 | E35: 6 | F35: 5
A36: Embauche
A37: Conseillers | B37: 1300
A38: Techniciens | B38: 1000 | E38: Stations de travail
A39: Licenciement | E39: Délai achat | F39: Tx usure
A40: Conseillers | B40: 4000 | E40: 0 | F40: =Paramètres!$B$23 -> 1
A41: Techniciens | B41: 5000 | E41: 1 | F41: =Paramètres!$B$24 -> 1
...
